2021-03-13 23:48:18,808 INFO    Thread-19 :1776 [wandb_setup.py:_flush():69] setting env: {'root_dir': 'C:\\Users\\rigve\\Documents\\IITM\\Courses\\DL 6910\\Github\\CS6910\\Assignment 1', 'project': 'Assignment 1', 'run_id': 'qanvihog', 'sweep_param_path': 'C:\\Users\\rigve\\Documents\\IITM\\Courses\\DL 6910\\Github\\CS6910\\Assignment 1\\wandb\\sweep-imakrin1\\config-qanvihog.yaml', 'sweep_id': 'imakrin1'}
2021-03-13 23:48:18,808 INFO    Thread-19 :1776 [wandb_setup.py:_flush():69] setting login settings: {}
2021-03-13 23:48:18,808 INFO    Thread-19 :1776 [wandb_init.py:_log_setup():334] Logging user logs to C:\Users\rigve\Documents\IITM\Courses\DL 6910\Github\CS6910\Assignment 1\wandb\run-20210313_234818-qanvihog\logs\debug.log
2021-03-13 23:48:18,809 INFO    Thread-19 :1776 [wandb_init.py:_log_setup():335] Logging internal logs to C:\Users\rigve\Documents\IITM\Courses\DL 6910\Github\CS6910\Assignment 1\wandb\run-20210313_234818-qanvihog\logs\debug-internal.log
2021-03-13 23:48:18,809 INFO    Thread-19 :1776 [wandb_init.py:_jupyter_setup():285] configuring jupyter hooks <wandb.sdk.wandb_init._WandbInit object at 0x0000018D8D115820>
2021-03-13 23:48:18,810 INFO    Thread-19 :1776 [wandb_init.py:init():367] calling init triggers
2021-03-13 23:48:18,810 INFO    Thread-19 :1776 [wandb_init.py:init():372] wandb.init called with sweep_config: {'ac': 'relu', 'batch_size': 64, 'epochs': 5, 'hidden_layer_size': 128, 'hidden_layers': 4, 'init_strategy': 'xavier', 'learning_rate': 0.001, 'optimiser': 'rmsprop', 'weight_decay': 0}
config: {}
2021-03-13 23:48:18,810 INFO    Thread-19 :1776 [wandb_init.py:init():416] starting backend
2021-03-13 23:48:18,810 INFO    Thread-19 :1776 [backend.py:_multiprocessing_setup():69] multiprocessing start_methods=spawn, using: spawn
2021-03-13 23:48:18,813 INFO    Thread-19 :1776 [backend.py:ensure_launched():123] starting backend process...
2021-03-13 23:48:18,881 INFO    Thread-19 :1776 [backend.py:ensure_launched():127] started backend process with pid: 21212
2021-03-13 23:48:18,881 INFO    Thread-19 :1776 [wandb_init.py:init():421] backend started and connected
2021-03-13 23:48:18,893 INFO    Thread-19 :1776 [wandb_run.py:_config_callback():733] config_cb None None {'ac': 'relu', 'batch_size': 64, 'epochs': 5, 'hidden_layer_size': 128, 'hidden_layers': 4, 'init_strategy': 'xavier', 'learning_rate': 0.001, 'optimiser': 'rmsprop', 'weight_decay': 0}
2021-03-13 23:48:18,893 INFO    Thread-19 :1776 [wandb_init.py:init():461] updated telemetry
2021-03-13 23:48:18,894 INFO    Thread-19 :1776 [wandb_init.py:init():480] communicating current version
2021-03-13 23:48:20,188 INFO    Thread-19 :1776 [wandb_init.py:init():485] got version response 
2021-03-13 23:48:20,188 INFO    Thread-19 :1776 [wandb_init.py:init():493] communicating run to backend with 30 second timeout
2021-03-13 23:48:21,278 INFO    Thread-19 :1776 [wandb_init.py:init():513] run resumed
2021-03-13 23:48:21,282 INFO    Thread-19 :1776 [wandb_init.py:init():518] starting run threads in backend
2021-03-13 23:48:24,267 INFO    Thread-19 :1776 [wandb_run.py:_console_start():1480] atexit reg
2021-03-13 23:48:24,273 INFO    Thread-19 :1776 [wandb_run.py:_redirect():1343] redirect: SettingsConsole.WRAP
2021-03-13 23:48:24,273 INFO    Thread-19 :1776 [wandb_run.py:_redirect():1378] Wrapping output streams.
2021-03-13 23:48:24,273 INFO    Thread-19 :1776 [wandb_run.py:_redirect():1394] Redirects installed.
2021-03-13 23:48:24,273 INFO    Thread-19 :1776 [wandb_init.py:init():542] run started, returning control to user process
2021-03-13 23:48:28,573 ERROR   Thread-10 :1776 [internal_api.py:execute():126] 429 response executing GraphQL.
2021-03-13 23:48:28,573 ERROR   Thread-10 :1776 [internal_api.py:execute():127] {"error":"rate limit exceeded"}

2021-03-13 23:48:29,930 ERROR   Thread-10 :1776 [internal_api.py:execute():126] 429 response executing GraphQL.
2021-03-13 23:48:29,930 ERROR   Thread-10 :1776 [internal_api.py:execute():127] {"error":"rate limit exceeded"}

2021-03-13 23:48:44,255 ERROR   Thread-10 :1776 [internal_api.py:execute():126] 429 response executing GraphQL.
2021-03-13 23:48:44,255 ERROR   Thread-10 :1776 [internal_api.py:execute():127] {"error":"rate limit exceeded"}

2021-03-13 23:48:58,565 ERROR   Thread-10 :1776 [internal_api.py:execute():126] 429 response executing GraphQL.
2021-03-13 23:48:58,566 ERROR   Thread-10 :1776 [internal_api.py:execute():127] {"error":"rate limit exceeded"}

2021-03-13 23:49:13,775 ERROR   Thread-10 :1776 [internal_api.py:execute():126] 429 response executing GraphQL.
2021-03-13 23:49:13,775 ERROR   Thread-10 :1776 [internal_api.py:execute():127] {"error":"rate limit exceeded"}

2021-03-13 23:49:29,461 ERROR   Thread-10 :1776 [internal_api.py:execute():126] 429 response executing GraphQL.
2021-03-13 23:49:29,461 ERROR   Thread-10 :1776 [internal_api.py:execute():127] {"error":"rate limit exceeded"}

2021-03-13 23:49:57,151 ERROR   Thread-10 :1776 [internal_api.py:execute():126] 429 response executing GraphQL.
2021-03-13 23:49:57,152 ERROR   Thread-10 :1776 [internal_api.py:execute():127] {"error":"rate limit exceeded"}

2021-03-13 23:49:58,760 ERROR   Thread-10 :1776 [internal_api.py:execute():126] 429 response executing GraphQL.
2021-03-13 23:49:58,771 ERROR   Thread-10 :1776 [internal_api.py:execute():127] {"error":"rate limit exceeded"}

2021-03-13 23:50:13,716 ERROR   Thread-10 :1776 [internal_api.py:execute():126] 429 response executing GraphQL.
2021-03-13 23:50:13,728 ERROR   Thread-10 :1776 [internal_api.py:execute():127] {"error":"rate limit exceeded"}

2021-03-13 23:50:28,972 ERROR   Thread-10 :1776 [internal_api.py:execute():126] 429 response executing GraphQL.
2021-03-13 23:50:28,972 ERROR   Thread-10 :1776 [internal_api.py:execute():127] {"error":"rate limit exceeded"}

2021-03-13 23:50:44,346 ERROR   Thread-10 :1776 [internal_api.py:execute():126] 429 response executing GraphQL.
2021-03-13 23:50:44,349 ERROR   Thread-10 :1776 [internal_api.py:execute():127] {"error":"rate limit exceeded"}

2021-03-13 23:50:55,569 ERROR   Thread-10 :1776 [internal_api.py:execute():126] 429 response executing GraphQL.
2021-03-13 23:50:55,579 ERROR   Thread-10 :1776 [internal_api.py:execute():127] {"error":"rate limit exceeded"}

2021-03-13 23:50:57,316 ERROR   Thread-10 :1776 [internal_api.py:execute():126] 429 response executing GraphQL.
2021-03-13 23:50:57,317 ERROR   Thread-10 :1776 [internal_api.py:execute():127] {"error":"rate limit exceeded"}

2021-03-13 23:50:59,963 ERROR   Thread-10 :1776 [internal_api.py:execute():126] 429 response executing GraphQL.
2021-03-13 23:50:59,974 ERROR   Thread-10 :1776 [internal_api.py:execute():127] {"error":"rate limit exceeded"}

2021-03-13 23:50:59,990 ERROR   Thread-10 :1776 [retry.py:__call__():111] Retry attempt failed:
Traceback (most recent call last):
  File "C:\Users\rigve\AppData\Roaming\Python\Python38\site-packages\wandb\old\retry.py", line 96, in __call__
    result = self._call_fn(*args, **kwargs)
  File "C:\Users\rigve\AppData\Roaming\Python\Python38\site-packages\wandb\sdk\internal\internal_api.py", line 129, in execute
    six.reraise(*sys.exc_info())
  File "C:\Users\rigve\AppData\Roaming\Python\Python38\site-packages\six.py", line 703, in reraise
    raise value
  File "C:\Users\rigve\AppData\Roaming\Python\Python38\site-packages\wandb\sdk\internal\internal_api.py", line 123, in execute
    return self.client.execute(*args, **kwargs)
  File "C:\Users\rigve\AppData\Roaming\Python\Python38\site-packages\wandb\vendor\gql-0.2.0\gql\client.py", line 52, in execute
    result = self._get_result(document, *args, **kwargs)
  File "C:\Users\rigve\AppData\Roaming\Python\Python38\site-packages\wandb\vendor\gql-0.2.0\gql\client.py", line 60, in _get_result
    return self.transport.execute(document, *args, **kwargs)
  File "C:\Users\rigve\AppData\Roaming\Python\Python38\site-packages\wandb\vendor\gql-0.2.0\gql\transport\requests.py", line 39, in execute
    request.raise_for_status()
  File "C:\Users\rigve\AppData\Roaming\Python\Python38\site-packages\requests\models.py", line 943, in raise_for_status
    raise HTTPError(http_error_msg, response=self)
requests.exceptions.HTTPError: 429 Client Error: Too Many Requests for url: https://api.wandb.ai/graphql
2021-03-13 23:51:25,311 ERROR   Thread-10 :1776 [internal_api.py:execute():126] 429 response executing GraphQL.
2021-03-13 23:51:25,312 ERROR   Thread-10 :1776 [internal_api.py:execute():127] {"error":"rate limit exceeded"}

2021-03-13 23:51:26,950 ERROR   Thread-10 :1776 [internal_api.py:execute():126] 429 response executing GraphQL.
2021-03-13 23:51:26,952 ERROR   Thread-10 :1776 [internal_api.py:execute():127] {"error":"rate limit exceeded"}

2021-03-13 23:51:29,457 ERROR   Thread-10 :1776 [internal_api.py:execute():126] 429 response executing GraphQL.
2021-03-13 23:51:29,458 ERROR   Thread-10 :1776 [internal_api.py:execute():127] {"error":"rate limit exceeded"}

2021-03-13 23:51:29,459 ERROR   Thread-10 :1776 [retry.py:__call__():111] Retry attempt failed:
Traceback (most recent call last):
  File "C:\Users\rigve\AppData\Roaming\Python\Python38\site-packages\wandb\old\retry.py", line 96, in __call__
    result = self._call_fn(*args, **kwargs)
  File "C:\Users\rigve\AppData\Roaming\Python\Python38\site-packages\wandb\sdk\internal\internal_api.py", line 129, in execute
    six.reraise(*sys.exc_info())
  File "C:\Users\rigve\AppData\Roaming\Python\Python38\site-packages\six.py", line 703, in reraise
    raise value
  File "C:\Users\rigve\AppData\Roaming\Python\Python38\site-packages\wandb\sdk\internal\internal_api.py", line 123, in execute
    return self.client.execute(*args, **kwargs)
  File "C:\Users\rigve\AppData\Roaming\Python\Python38\site-packages\wandb\vendor\gql-0.2.0\gql\client.py", line 52, in execute
    result = self._get_result(document, *args, **kwargs)
  File "C:\Users\rigve\AppData\Roaming\Python\Python38\site-packages\wandb\vendor\gql-0.2.0\gql\client.py", line 60, in _get_result
    return self.transport.execute(document, *args, **kwargs)
  File "C:\Users\rigve\AppData\Roaming\Python\Python38\site-packages\wandb\vendor\gql-0.2.0\gql\transport\requests.py", line 39, in execute
    request.raise_for_status()
  File "C:\Users\rigve\AppData\Roaming\Python\Python38\site-packages\requests\models.py", line 943, in raise_for_status
    raise HTTPError(http_error_msg, response=self)
requests.exceptions.HTTPError: 429 Client Error: Too Many Requests for url: https://api.wandb.ai/graphql
2021-03-13 23:51:56,058 ERROR   Thread-10 :1776 [internal_api.py:execute():126] 429 response executing GraphQL.
2021-03-13 23:51:56,059 ERROR   Thread-10 :1776 [internal_api.py:execute():127] {"error":"rate limit exceeded"}

2021-03-13 23:51:57,534 ERROR   Thread-10 :1776 [internal_api.py:execute():126] 429 response executing GraphQL.
2021-03-13 23:51:57,535 ERROR   Thread-10 :1776 [internal_api.py:execute():127] {"error":"rate limit exceeded"}

2021-03-13 23:52:26,270 ERROR   Thread-10 :1776 [internal_api.py:execute():126] 429 response executing GraphQL.
2021-03-13 23:52:26,281 ERROR   Thread-10 :1776 [internal_api.py:execute():127] {"error":"rate limit exceeded"}

2021-03-13 23:52:28,013 ERROR   Thread-10 :1776 [internal_api.py:execute():126] 429 response executing GraphQL.
2021-03-13 23:52:28,014 ERROR   Thread-10 :1776 [internal_api.py:execute():127] {"error":"rate limit exceeded"}

2021-03-13 23:52:43,391 ERROR   Thread-10 :1776 [internal_api.py:execute():126] 429 response executing GraphQL.
2021-03-13 23:52:43,392 ERROR   Thread-10 :1776 [internal_api.py:execute():127] {"error":"rate limit exceeded"}

2021-03-13 23:52:44,873 ERROR   Thread-10 :1776 [internal_api.py:execute():126] 429 response executing GraphQL.
2021-03-13 23:52:44,874 ERROR   Thread-10 :1776 [internal_api.py:execute():127] {"error":"rate limit exceeded"}

2021-03-13 23:52:56,582 ERROR   Thread-10 :1776 [internal_api.py:execute():126] 429 response executing GraphQL.
2021-03-13 23:52:56,583 ERROR   Thread-10 :1776 [internal_api.py:execute():127] {"error":"rate limit exceeded"}

2021-03-13 23:52:58,184 ERROR   Thread-10 :1776 [internal_api.py:execute():126] 429 response executing GraphQL.
2021-03-13 23:52:58,189 ERROR   Thread-10 :1776 [internal_api.py:execute():127] {"error":"rate limit exceeded"}

2021-03-13 23:53:13,905 ERROR   Thread-10 :1776 [internal_api.py:execute():126] 429 response executing GraphQL.
2021-03-13 23:53:13,905 ERROR   Thread-10 :1776 [internal_api.py:execute():127] {"error":"rate limit exceeded"}

2021-03-13 23:53:28,054 ERROR   Thread-10 :1776 [internal_api.py:execute():126] 429 response executing GraphQL.
2021-03-13 23:53:28,054 ERROR   Thread-10 :1776 [internal_api.py:execute():127] {"error":"rate limit exceeded"}

2021-03-13 23:53:29,835 ERROR   Thread-10 :1776 [internal_api.py:execute():126] 429 response executing GraphQL.
2021-03-13 23:53:29,836 ERROR   Thread-10 :1776 [internal_api.py:execute():127] {"error":"rate limit exceeded"}

2021-03-13 23:53:42,710 ERROR   Thread-10 :1776 [internal_api.py:execute():126] 429 response executing GraphQL.
2021-03-13 23:53:42,720 ERROR   Thread-10 :1776 [internal_api.py:execute():127] {"error":"rate limit exceeded"}

2021-03-13 23:53:44,416 ERROR   Thread-10 :1776 [internal_api.py:execute():126] 429 response executing GraphQL.
2021-03-13 23:53:44,421 ERROR   Thread-10 :1776 [internal_api.py:execute():127] {"error":"rate limit exceeded"}

2021-03-13 23:53:56,962 ERROR   Thread-10 :1776 [internal_api.py:execute():126] 429 response executing GraphQL.
2021-03-13 23:53:56,962 ERROR   Thread-10 :1776 [internal_api.py:execute():127] {"error":"rate limit exceeded"}

2021-03-13 23:53:58,550 ERROR   Thread-10 :1776 [internal_api.py:execute():126] 429 response executing GraphQL.
2021-03-13 23:53:58,551 ERROR   Thread-10 :1776 [internal_api.py:execute():127] {"error":"rate limit exceeded"}

2021-03-13 23:54:14,050 ERROR   Thread-10 :1776 [internal_api.py:execute():126] 429 response executing GraphQL.
2021-03-13 23:54:14,058 ERROR   Thread-10 :1776 [internal_api.py:execute():127] {"error":"rate limit exceeded"}

2021-03-13 23:54:25,960 ERROR   Thread-10 :1776 [internal_api.py:execute():126] 429 response executing GraphQL.
2021-03-13 23:54:25,971 ERROR   Thread-10 :1776 [internal_api.py:execute():127] {"error":"rate limit exceeded"}

2021-03-13 23:54:27,555 ERROR   Thread-10 :1776 [internal_api.py:execute():126] 429 response executing GraphQL.
2021-03-13 23:54:27,556 ERROR   Thread-10 :1776 [internal_api.py:execute():127] {"error":"rate limit exceeded"}

2021-03-13 23:54:43,989 ERROR   Thread-10 :1776 [internal_api.py:execute():126] 429 response executing GraphQL.
2021-03-13 23:54:43,990 ERROR   Thread-10 :1776 [internal_api.py:execute():127] {"error":"rate limit exceeded"}

2021-03-13 23:54:57,042 ERROR   Thread-10 :1776 [internal_api.py:execute():126] 429 response executing GraphQL.
2021-03-13 23:54:57,042 ERROR   Thread-10 :1776 [internal_api.py:execute():127] {"error":"rate limit exceeded"}

2021-03-13 23:54:58,758 ERROR   Thread-10 :1776 [internal_api.py:execute():126] 429 response executing GraphQL.
2021-03-13 23:54:58,758 ERROR   Thread-10 :1776 [internal_api.py:execute():127] {"error":"rate limit exceeded"}

2021-03-13 23:55:11,805 ERROR   Thread-10 :1776 [internal_api.py:execute():126] 429 response executing GraphQL.
2021-03-13 23:55:11,806 ERROR   Thread-10 :1776 [internal_api.py:execute():127] {"error":"rate limit exceeded"}

2021-03-13 23:55:13,521 ERROR   Thread-10 :1776 [internal_api.py:execute():126] 429 response executing GraphQL.
2021-03-13 23:55:13,523 ERROR   Thread-10 :1776 [internal_api.py:execute():127] {"error":"rate limit exceeded"}

2021-03-13 23:55:25,788 ERROR   Thread-10 :1776 [internal_api.py:execute():126] 429 response executing GraphQL.
2021-03-13 23:55:25,790 ERROR   Thread-10 :1776 [internal_api.py:execute():127] {"error":"rate limit exceeded"}

2021-03-13 23:55:27,428 ERROR   Thread-10 :1776 [internal_api.py:execute():126] 429 response executing GraphQL.
2021-03-13 23:55:27,429 ERROR   Thread-10 :1776 [internal_api.py:execute():127] {"error":"rate limit exceeded"}

2021-03-13 23:55:44,215 ERROR   Thread-10 :1776 [internal_api.py:execute():126] 429 response executing GraphQL.
2021-03-13 23:55:44,216 ERROR   Thread-10 :1776 [internal_api.py:execute():127] {"error":"rate limit exceeded"}

2021-03-13 23:55:55,973 ERROR   Thread-10 :1776 [internal_api.py:execute():126] 429 response executing GraphQL.
2021-03-13 23:55:55,974 ERROR   Thread-10 :1776 [internal_api.py:execute():127] {"error":"rate limit exceeded"}

2021-03-13 23:55:57,498 ERROR   Thread-10 :1776 [internal_api.py:execute():126] 429 response executing GraphQL.
2021-03-13 23:55:57,499 ERROR   Thread-10 :1776 [internal_api.py:execute():127] {"error":"rate limit exceeded"}

2021-03-13 23:56:13,395 ERROR   Thread-10 :1776 [internal_api.py:execute():126] 429 response executing GraphQL.
2021-03-13 23:56:13,396 ERROR   Thread-10 :1776 [internal_api.py:execute():127] {"error":"rate limit exceeded"}

2021-03-13 23:56:27,516 ERROR   Thread-10 :1776 [internal_api.py:execute():126] 429 response executing GraphQL.
2021-03-13 23:56:27,517 ERROR   Thread-10 :1776 [internal_api.py:execute():127] {"error":"rate limit exceeded"}

2021-03-13 23:56:29,128 ERROR   Thread-10 :1776 [internal_api.py:execute():126] 429 response executing GraphQL.
2021-03-13 23:56:29,130 ERROR   Thread-10 :1776 [internal_api.py:execute():127] {"error":"rate limit exceeded"}

2021-03-13 23:56:42,856 ERROR   Thread-10 :1776 [internal_api.py:execute():126] 429 response executing GraphQL.
2021-03-13 23:56:42,857 ERROR   Thread-10 :1776 [internal_api.py:execute():127] {"error":"rate limit exceeded"}

2021-03-13 23:56:44,390 ERROR   Thread-10 :1776 [internal_api.py:execute():126] 429 response executing GraphQL.
2021-03-13 23:56:44,391 ERROR   Thread-10 :1776 [internal_api.py:execute():127] {"error":"rate limit exceeded"}

2021-03-13 23:56:55,834 ERROR   Thread-10 :1776 [internal_api.py:execute():126] 429 response executing GraphQL.
2021-03-13 23:56:55,836 ERROR   Thread-10 :1776 [internal_api.py:execute():127] {"error":"rate limit exceeded"}

2021-03-13 23:56:57,418 ERROR   Thread-10 :1776 [internal_api.py:execute():126] 429 response executing GraphQL.
2021-03-13 23:56:57,418 ERROR   Thread-10 :1776 [internal_api.py:execute():127] {"error":"rate limit exceeded"}

2021-03-13 23:57:13,955 ERROR   Thread-10 :1776 [internal_api.py:execute():126] 429 response executing GraphQL.
2021-03-13 23:57:13,956 ERROR   Thread-10 :1776 [internal_api.py:execute():127] {"error":"rate limit exceeded"}

2021-03-13 23:57:26,031 ERROR   Thread-10 :1776 [internal_api.py:execute():126] 429 response executing GraphQL.
2021-03-13 23:57:26,032 ERROR   Thread-10 :1776 [internal_api.py:execute():127] {"error":"rate limit exceeded"}

2021-03-13 23:57:27,672 ERROR   Thread-10 :1776 [internal_api.py:execute():126] 429 response executing GraphQL.
2021-03-13 23:57:27,674 ERROR   Thread-10 :1776 [internal_api.py:execute():127] {"error":"rate limit exceeded"}

2021-03-13 23:57:57,514 ERROR   Thread-10 :1776 [internal_api.py:execute():126] 429 response executing GraphQL.
2021-03-13 23:57:57,515 ERROR   Thread-10 :1776 [internal_api.py:execute():127] {"error":"rate limit exceeded"}

2021-03-13 23:57:58,971 ERROR   Thread-10 :1776 [internal_api.py:execute():126] 429 response executing GraphQL.
2021-03-13 23:57:58,973 ERROR   Thread-10 :1776 [internal_api.py:execute():127] {"error":"rate limit exceeded"}

2021-03-13 23:58:12,447 ERROR   Thread-10 :1776 [internal_api.py:execute():126] 429 response executing GraphQL.
2021-03-13 23:58:12,448 ERROR   Thread-10 :1776 [internal_api.py:execute():127] {"error":"rate limit exceeded"}

2021-03-13 23:58:13,971 ERROR   Thread-10 :1776 [internal_api.py:execute():126] 429 response executing GraphQL.
2021-03-13 23:58:13,972 ERROR   Thread-10 :1776 [internal_api.py:execute():127] {"error":"rate limit exceeded"}

2021-03-13 23:58:27,312 ERROR   Thread-10 :1776 [internal_api.py:execute():126] 429 response executing GraphQL.
2021-03-13 23:58:27,312 ERROR   Thread-10 :1776 [internal_api.py:execute():127] {"error":"rate limit exceeded"}

2021-03-13 23:58:28,861 ERROR   Thread-10 :1776 [internal_api.py:execute():126] 429 response executing GraphQL.
2021-03-13 23:58:28,862 ERROR   Thread-10 :1776 [internal_api.py:execute():127] {"error":"rate limit exceeded"}

2021-03-13 23:58:44,260 ERROR   Thread-10 :1776 [internal_api.py:execute():126] 429 response executing GraphQL.
2021-03-13 23:58:44,262 ERROR   Thread-10 :1776 [internal_api.py:execute():127] {"error":"rate limit exceeded"}

2021-03-13 23:58:55,915 ERROR   Thread-10 :1776 [internal_api.py:execute():126] 429 response executing GraphQL.
2021-03-13 23:58:55,916 ERROR   Thread-10 :1776 [internal_api.py:execute():127] {"error":"rate limit exceeded"}

2021-03-13 23:58:57,643 ERROR   Thread-10 :1776 [internal_api.py:execute():126] 429 response executing GraphQL.
2021-03-13 23:58:57,645 ERROR   Thread-10 :1776 [internal_api.py:execute():127] {"error":"rate limit exceeded"}

2021-03-13 23:59:26,480 ERROR   Thread-10 :1776 [internal_api.py:execute():126] 429 response executing GraphQL.
2021-03-13 23:59:26,481 ERROR   Thread-10 :1776 [internal_api.py:execute():127] {"error":"rate limit exceeded"}

2021-03-13 23:59:28,157 ERROR   Thread-10 :1776 [internal_api.py:execute():126] 429 response executing GraphQL.
2021-03-13 23:59:28,159 ERROR   Thread-10 :1776 [internal_api.py:execute():127] {"error":"rate limit exceeded"}

2021-03-13 23:59:42,585 ERROR   Thread-10 :1776 [internal_api.py:execute():126] 429 response executing GraphQL.
2021-03-13 23:59:42,586 ERROR   Thread-10 :1776 [internal_api.py:execute():127] {"error":"rate limit exceeded"}

2021-03-13 23:59:44,312 ERROR   Thread-10 :1776 [internal_api.py:execute():126] 429 response executing GraphQL.
2021-03-13 23:59:44,312 ERROR   Thread-10 :1776 [internal_api.py:execute():127] {"error":"rate limit exceeded"}

2021-03-13 23:59:56,578 ERROR   Thread-10 :1776 [internal_api.py:execute():126] 429 response executing GraphQL.
2021-03-13 23:59:56,578 ERROR   Thread-10 :1776 [internal_api.py:execute():127] {"error":"rate limit exceeded"}

2021-03-13 23:59:58,259 ERROR   Thread-10 :1776 [internal_api.py:execute():126] 429 response executing GraphQL.
2021-03-13 23:59:58,260 ERROR   Thread-10 :1776 [internal_api.py:execute():127] {"error":"rate limit exceeded"}

2021-03-14 00:00:14,922 ERROR   Thread-10 :1776 [internal_api.py:execute():126] 429 response executing GraphQL.
2021-03-14 00:00:14,924 ERROR   Thread-10 :1776 [internal_api.py:execute():127] {"error":"rate limit exceeded"}

2021-03-14 00:00:25,940 ERROR   Thread-10 :1776 [internal_api.py:execute():126] 429 response executing GraphQL.
2021-03-14 00:00:25,941 ERROR   Thread-10 :1776 [internal_api.py:execute():127] {"error":"rate limit exceeded"}

2021-03-14 00:00:27,588 ERROR   Thread-10 :1776 [internal_api.py:execute():126] 429 response executing GraphQL.
2021-03-14 00:00:27,588 ERROR   Thread-10 :1776 [internal_api.py:execute():127] {"error":"rate limit exceeded"}

2021-03-14 00:00:43,855 ERROR   Thread-10 :1776 [internal_api.py:execute():126] 429 response executing GraphQL.
2021-03-14 00:00:43,856 ERROR   Thread-10 :1776 [internal_api.py:execute():127] {"error":"rate limit exceeded"}

2021-03-14 00:00:56,672 ERROR   Thread-10 :1776 [internal_api.py:execute():126] 429 response executing GraphQL.
2021-03-14 00:00:56,674 ERROR   Thread-10 :1776 [internal_api.py:execute():127] {"error":"rate limit exceeded"}

2021-03-14 00:00:58,525 ERROR   Thread-10 :1776 [internal_api.py:execute():126] 429 response executing GraphQL.
2021-03-14 00:00:58,525 ERROR   Thread-10 :1776 [internal_api.py:execute():127] {"error":"rate limit exceeded"}

2021-03-14 00:01:11,575 ERROR   Thread-10 :1776 [internal_api.py:execute():126] 429 response executing GraphQL.
2021-03-14 00:01:11,584 ERROR   Thread-10 :1776 [internal_api.py:execute():127] {"error":"rate limit exceeded"}

2021-03-14 00:01:13,351 ERROR   Thread-10 :1776 [internal_api.py:execute():126] 429 response executing GraphQL.
2021-03-14 00:01:13,354 ERROR   Thread-10 :1776 [internal_api.py:execute():127] {"error":"rate limit exceeded"}

2021-03-14 00:01:28,900 ERROR   Thread-10 :1776 [internal_api.py:execute():126] 429 response executing GraphQL.
2021-03-14 00:01:28,900 ERROR   Thread-10 :1776 [internal_api.py:execute():127] {"error":"rate limit exceeded"}

2021-03-14 00:01:42,941 ERROR   Thread-10 :1776 [internal_api.py:execute():126] 429 response executing GraphQL.
2021-03-14 00:01:42,952 ERROR   Thread-10 :1776 [internal_api.py:execute():127] {"error":"rate limit exceeded"}

2021-03-14 00:01:44,501 ERROR   Thread-10 :1776 [internal_api.py:execute():126] 429 response executing GraphQL.
2021-03-14 00:01:44,501 ERROR   Thread-10 :1776 [internal_api.py:execute():127] {"error":"rate limit exceeded"}

2021-03-14 00:01:57,432 ERROR   Thread-10 :1776 [internal_api.py:execute():126] 429 response executing GraphQL.
2021-03-14 00:01:57,432 ERROR   Thread-10 :1776 [internal_api.py:execute():127] {"error":"rate limit exceeded"}

2021-03-14 00:01:59,125 ERROR   Thread-10 :1776 [internal_api.py:execute():126] 429 response executing GraphQL.
2021-03-14 00:01:59,125 ERROR   Thread-10 :1776 [internal_api.py:execute():127] {"error":"rate limit exceeded"}

2021-03-14 00:02:12,217 ERROR   Thread-10 :1776 [internal_api.py:execute():126] 429 response executing GraphQL.
2021-03-14 00:02:12,218 ERROR   Thread-10 :1776 [internal_api.py:execute():127] {"error":"rate limit exceeded"}

2021-03-14 00:02:13,759 ERROR   Thread-10 :1776 [internal_api.py:execute():126] 429 response executing GraphQL.
2021-03-14 00:02:13,760 ERROR   Thread-10 :1776 [internal_api.py:execute():127] {"error":"rate limit exceeded"}

2021-03-14 00:02:26,217 ERROR   Thread-10 :1776 [internal_api.py:execute():126] 429 response executing GraphQL.
2021-03-14 00:02:26,217 ERROR   Thread-10 :1776 [internal_api.py:execute():127] {"error":"rate limit exceeded"}

2021-03-14 00:02:27,965 ERROR   Thread-10 :1776 [internal_api.py:execute():126] 429 response executing GraphQL.
2021-03-14 00:02:27,967 ERROR   Thread-10 :1776 [internal_api.py:execute():127] {"error":"rate limit exceeded"}

2021-03-14 00:02:43,935 ERROR   Thread-10 :1776 [internal_api.py:execute():126] 429 response executing GraphQL.
2021-03-14 00:02:43,935 ERROR   Thread-10 :1776 [internal_api.py:execute():127] {"error":"rate limit exceeded"}

2021-03-14 00:02:57,125 ERROR   Thread-10 :1776 [internal_api.py:execute():126] 429 response executing GraphQL.
2021-03-14 00:02:57,136 ERROR   Thread-10 :1776 [internal_api.py:execute():127] {"error":"rate limit exceeded"}

2021-03-14 00:02:58,691 ERROR   Thread-10 :1776 [internal_api.py:execute():126] 429 response executing GraphQL.
2021-03-14 00:02:58,691 ERROR   Thread-10 :1776 [internal_api.py:execute():127] {"error":"rate limit exceeded"}

2021-03-14 00:03:13,178 ERROR   Thread-10 :1776 [internal_api.py:execute():126] 429 response executing GraphQL.
2021-03-14 00:03:13,180 ERROR   Thread-10 :1776 [internal_api.py:execute():127] {"error":"rate limit exceeded"}

2021-03-14 00:03:14,871 ERROR   Thread-10 :1776 [internal_api.py:execute():126] 429 response executing GraphQL.
2021-03-14 00:03:14,871 ERROR   Thread-10 :1776 [internal_api.py:execute():127] {"error":"rate limit exceeded"}

2021-03-14 00:03:26,665 ERROR   Thread-10 :1776 [internal_api.py:execute():126] 429 response executing GraphQL.
2021-03-14 00:03:26,666 ERROR   Thread-10 :1776 [internal_api.py:execute():127] {"error":"rate limit exceeded"}

2021-03-14 00:03:28,190 ERROR   Thread-10 :1776 [internal_api.py:execute():126] 429 response executing GraphQL.
2021-03-14 00:03:28,191 ERROR   Thread-10 :1776 [internal_api.py:execute():127] {"error":"rate limit exceeded"}

2021-03-14 00:03:43,907 ERROR   Thread-10 :1776 [internal_api.py:execute():126] 429 response executing GraphQL.
2021-03-14 00:03:43,912 ERROR   Thread-10 :1776 [internal_api.py:execute():127] {"error":"rate limit exceeded"}

2021-03-14 00:03:56,446 ERROR   Thread-10 :1776 [internal_api.py:execute():126] 429 response executing GraphQL.
2021-03-14 00:03:56,447 ERROR   Thread-10 :1776 [internal_api.py:execute():127] {"error":"rate limit exceeded"}

2021-03-14 00:03:58,035 ERROR   Thread-10 :1776 [internal_api.py:execute():126] 429 response executing GraphQL.
2021-03-14 00:03:58,045 ERROR   Thread-10 :1776 [internal_api.py:execute():127] {"error":"rate limit exceeded"}

2021-03-14 00:04:28,507 ERROR   Thread-10 :1776 [internal_api.py:execute():126] 429 response executing GraphQL.
2021-03-14 00:04:28,518 ERROR   Thread-10 :1776 [internal_api.py:execute():127] {"error":"rate limit exceeded"}

2021-03-14 00:04:42,044 ERROR   Thread-10 :1776 [internal_api.py:execute():126] 429 response executing GraphQL.
2021-03-14 00:04:42,045 ERROR   Thread-10 :1776 [internal_api.py:execute():127] {"error":"rate limit exceeded"}

2021-03-14 00:04:43,718 ERROR   Thread-10 :1776 [internal_api.py:execute():126] 429 response executing GraphQL.
2021-03-14 00:04:43,719 ERROR   Thread-10 :1776 [internal_api.py:execute():127] {"error":"rate limit exceeded"}

2021-03-14 00:04:57,002 ERROR   Thread-10 :1776 [internal_api.py:execute():126] 429 response executing GraphQL.
2021-03-14 00:04:57,012 ERROR   Thread-10 :1776 [internal_api.py:execute():127] {"error":"rate limit exceeded"}

2021-03-14 00:04:58,687 ERROR   Thread-10 :1776 [internal_api.py:execute():126] 429 response executing GraphQL.
2021-03-14 00:04:58,688 ERROR   Thread-10 :1776 [internal_api.py:execute():127] {"error":"rate limit exceeded"}

2021-03-14 00:05:13,507 ERROR   Thread-10 :1776 [internal_api.py:execute():126] 429 response executing GraphQL.
2021-03-14 00:05:13,507 ERROR   Thread-10 :1776 [internal_api.py:execute():127] {"error":"rate limit exceeded"}

2021-03-14 00:05:26,980 ERROR   Thread-10 :1776 [internal_api.py:execute():126] 429 response executing GraphQL.
2021-03-14 00:05:26,980 ERROR   Thread-10 :1776 [internal_api.py:execute():127] {"error":"rate limit exceeded"}

2021-03-14 00:05:29,220 ERROR   Thread-10 :1776 [internal_api.py:execute():126] 429 response executing GraphQL.
2021-03-14 00:05:29,232 ERROR   Thread-10 :1776 [internal_api.py:execute():127] {"error":"rate limit exceeded"}

2021-03-14 00:05:42,844 ERROR   Thread-10 :1776 [internal_api.py:execute():126] 429 response executing GraphQL.
2021-03-14 00:05:42,857 ERROR   Thread-10 :1776 [internal_api.py:execute():127] {"error":"rate limit exceeded"}

2021-03-14 00:05:44,551 ERROR   Thread-10 :1776 [internal_api.py:execute():126] 429 response executing GraphQL.
2021-03-14 00:05:44,568 ERROR   Thread-10 :1776 [internal_api.py:execute():127] {"error":"rate limit exceeded"}

2021-03-14 00:05:57,197 ERROR   Thread-10 :1776 [internal_api.py:execute():126] 429 response executing GraphQL.
2021-03-14 00:05:57,198 ERROR   Thread-10 :1776 [internal_api.py:execute():127] {"error":"rate limit exceeded"}

2021-03-14 00:05:58,637 ERROR   Thread-10 :1776 [internal_api.py:execute():126] 429 response executing GraphQL.
2021-03-14 00:05:58,638 ERROR   Thread-10 :1776 [internal_api.py:execute():127] {"error":"rate limit exceeded"}

2021-03-14 00:06:11,033 ERROR   Thread-10 :1776 [internal_api.py:execute():126] 429 response executing GraphQL.
2021-03-14 00:06:11,043 ERROR   Thread-10 :1776 [internal_api.py:execute():127] {"error":"rate limit exceeded"}

2021-03-14 00:06:12,740 ERROR   Thread-10 :1776 [internal_api.py:execute():126] 429 response executing GraphQL.
2021-03-14 00:06:12,740 ERROR   Thread-10 :1776 [internal_api.py:execute():127] {"error":"rate limit exceeded"}

2021-03-14 00:06:41,826 ERROR   Thread-10 :1776 [internal_api.py:execute():126] 429 response executing GraphQL.
2021-03-14 00:06:41,828 ERROR   Thread-10 :1776 [internal_api.py:execute():127] {"error":"rate limit exceeded"}

2021-03-14 00:06:43,543 ERROR   Thread-10 :1776 [internal_api.py:execute():126] 429 response executing GraphQL.
2021-03-14 00:06:43,543 ERROR   Thread-10 :1776 [internal_api.py:execute():127] {"error":"rate limit exceeded"}

2021-03-14 00:06:59,678 ERROR   Thread-10 :1776 [internal_api.py:execute():126] 429 response executing GraphQL.
2021-03-14 00:06:59,691 ERROR   Thread-10 :1776 [internal_api.py:execute():127] {"error":"rate limit exceeded"}

2021-03-14 00:07:11,215 ERROR   Thread-10 :1776 [internal_api.py:execute():126] 429 response executing GraphQL.
2021-03-14 00:07:11,255 ERROR   Thread-10 :1776 [internal_api.py:execute():127] {"error":"rate limit exceeded"}

2021-03-14 00:07:13,041 ERROR   Thread-10 :1776 [internal_api.py:execute():126] 429 response executing GraphQL.
2021-03-14 00:07:13,043 ERROR   Thread-10 :1776 [internal_api.py:execute():127] {"error":"rate limit exceeded"}

2021-03-14 00:07:29,061 ERROR   Thread-10 :1776 [internal_api.py:execute():126] 429 response executing GraphQL.
2021-03-14 00:07:29,063 ERROR   Thread-10 :1776 [internal_api.py:execute():127] {"error":"rate limit exceeded"}

2021-03-14 00:07:41,108 ERROR   Thread-10 :1776 [internal_api.py:execute():126] 429 response executing GraphQL.
2021-03-14 00:07:41,109 ERROR   Thread-10 :1776 [internal_api.py:execute():127] {"error":"rate limit exceeded"}

2021-03-14 00:07:42,813 ERROR   Thread-10 :1776 [internal_api.py:execute():126] 429 response executing GraphQL.
2021-03-14 00:07:42,814 ERROR   Thread-10 :1776 [internal_api.py:execute():127] {"error":"rate limit exceeded"}

2021-03-14 00:08:12,014 ERROR   Thread-10 :1776 [internal_api.py:execute():126] 429 response executing GraphQL.
2021-03-14 00:08:12,015 ERROR   Thread-10 :1776 [internal_api.py:execute():127] {"error":"rate limit exceeded"}

2021-03-14 00:08:13,663 ERROR   Thread-10 :1776 [internal_api.py:execute():126] 429 response executing GraphQL.
2021-03-14 00:08:13,673 ERROR   Thread-10 :1776 [internal_api.py:execute():127] {"error":"rate limit exceeded"}

2021-03-14 00:08:26,307 ERROR   Thread-10 :1776 [internal_api.py:execute():126] 429 response executing GraphQL.
2021-03-14 00:08:26,307 ERROR   Thread-10 :1776 [internal_api.py:execute():127] {"error":"rate limit exceeded"}

2021-03-14 00:08:27,927 ERROR   Thread-10 :1776 [internal_api.py:execute():126] 429 response executing GraphQL.
2021-03-14 00:08:27,928 ERROR   Thread-10 :1776 [internal_api.py:execute():127] {"error":"rate limit exceeded"}

2021-03-14 00:08:44,364 ERROR   Thread-10 :1776 [internal_api.py:execute():126] 429 response executing GraphQL.
2021-03-14 00:08:44,373 ERROR   Thread-10 :1776 [internal_api.py:execute():127] {"error":"rate limit exceeded"}

2021-03-14 00:08:56,977 ERROR   Thread-10 :1776 [internal_api.py:execute():126] 429 response executing GraphQL.
2021-03-14 00:08:56,978 ERROR   Thread-10 :1776 [internal_api.py:execute():127] {"error":"rate limit exceeded"}

2021-03-14 00:08:58,644 ERROR   Thread-10 :1776 [internal_api.py:execute():126] 429 response executing GraphQL.
2021-03-14 00:08:58,645 ERROR   Thread-10 :1776 [internal_api.py:execute():127] {"error":"rate limit exceeded"}

2021-03-14 00:09:12,603 ERROR   Thread-10 :1776 [internal_api.py:execute():126] 429 response executing GraphQL.
2021-03-14 00:09:12,604 ERROR   Thread-10 :1776 [internal_api.py:execute():127] {"error":"rate limit exceeded"}

2021-03-14 00:09:14,233 ERROR   Thread-10 :1776 [internal_api.py:execute():126] 429 response executing GraphQL.
2021-03-14 00:09:14,234 ERROR   Thread-10 :1776 [internal_api.py:execute():127] {"error":"rate limit exceeded"}

2021-03-14 00:09:29,061 ERROR   Thread-10 :1776 [internal_api.py:execute():126] 429 response executing GraphQL.
2021-03-14 00:09:29,062 ERROR   Thread-10 :1776 [internal_api.py:execute():127] {"error":"rate limit exceeded"}

2021-03-14 00:09:41,448 ERROR   Thread-10 :1776 [internal_api.py:execute():126] 429 response executing GraphQL.
2021-03-14 00:09:41,450 ERROR   Thread-10 :1776 [internal_api.py:execute():127] {"error":"rate limit exceeded"}

2021-03-14 00:09:43,291 ERROR   Thread-10 :1776 [internal_api.py:execute():126] 429 response executing GraphQL.
2021-03-14 00:09:43,291 ERROR   Thread-10 :1776 [internal_api.py:execute():127] {"error":"rate limit exceeded"}

2021-03-14 00:10:11,611 ERROR   Thread-10 :1776 [internal_api.py:execute():126] 429 response executing GraphQL.
2021-03-14 00:10:11,611 ERROR   Thread-10 :1776 [internal_api.py:execute():127] {"error":"rate limit exceeded"}

2021-03-14 00:10:13,184 ERROR   Thread-10 :1776 [internal_api.py:execute():126] 429 response executing GraphQL.
2021-03-14 00:10:13,185 ERROR   Thread-10 :1776 [internal_api.py:execute():127] {"error":"rate limit exceeded"}

2021-03-14 00:10:27,995 ERROR   Thread-10 :1776 [internal_api.py:execute():126] 429 response executing GraphQL.
2021-03-14 00:10:27,997 ERROR   Thread-10 :1776 [internal_api.py:execute():127] {"error":"rate limit exceeded"}

2021-03-14 00:10:29,571 ERROR   Thread-10 :1776 [internal_api.py:execute():126] 429 response executing GraphQL.
2021-03-14 00:10:29,572 ERROR   Thread-10 :1776 [internal_api.py:execute():127] {"error":"rate limit exceeded"}

2021-03-14 00:10:42,994 ERROR   Thread-10 :1776 [internal_api.py:execute():126] 429 response executing GraphQL.
2021-03-14 00:10:42,995 ERROR   Thread-10 :1776 [internal_api.py:execute():127] {"error":"rate limit exceeded"}

2021-03-14 00:10:44,637 ERROR   Thread-10 :1776 [internal_api.py:execute():126] 429 response executing GraphQL.
2021-03-14 00:10:44,637 ERROR   Thread-10 :1776 [internal_api.py:execute():127] {"error":"rate limit exceeded"}

2021-03-14 00:10:58,317 ERROR   Thread-10 :1776 [internal_api.py:execute():126] 429 response executing GraphQL.
2021-03-14 00:10:58,318 ERROR   Thread-10 :1776 [internal_api.py:execute():127] {"error":"rate limit exceeded"}

2021-03-14 00:10:59,866 ERROR   Thread-10 :1776 [internal_api.py:execute():126] 429 response executing GraphQL.
2021-03-14 00:10:59,868 ERROR   Thread-10 :1776 [internal_api.py:execute():127] {"error":"rate limit exceeded"}

2021-03-14 00:11:12,901 ERROR   Thread-10 :1776 [internal_api.py:execute():126] 429 response executing GraphQL.
2021-03-14 00:11:12,901 ERROR   Thread-10 :1776 [internal_api.py:execute():127] {"error":"rate limit exceeded"}

2021-03-14 00:11:14,434 ERROR   Thread-10 :1776 [internal_api.py:execute():126] 429 response executing GraphQL.
2021-03-14 00:11:14,444 ERROR   Thread-10 :1776 [internal_api.py:execute():127] {"error":"rate limit exceeded"}

2021-03-14 00:11:26,291 ERROR   Thread-10 :1776 [internal_api.py:execute():126] 429 response executing GraphQL.
2021-03-14 00:11:26,293 ERROR   Thread-10 :1776 [internal_api.py:execute():127] {"error":"rate limit exceeded"}

2021-03-14 00:11:27,880 ERROR   Thread-10 :1776 [internal_api.py:execute():126] 429 response executing GraphQL.
2021-03-14 00:11:27,882 ERROR   Thread-10 :1776 [internal_api.py:execute():127] {"error":"rate limit exceeded"}

2021-03-14 00:11:44,900 ERROR   Thread-10 :1776 [internal_api.py:execute():126] 429 response executing GraphQL.
2021-03-14 00:11:44,901 ERROR   Thread-10 :1776 [internal_api.py:execute():127] {"error":"rate limit exceeded"}

2021-03-14 00:11:56,468 ERROR   Thread-10 :1776 [internal_api.py:execute():126] 429 response executing GraphQL.
2021-03-14 00:11:56,469 ERROR   Thread-10 :1776 [internal_api.py:execute():127] {"error":"rate limit exceeded"}

2021-03-14 00:11:58,147 ERROR   Thread-10 :1776 [internal_api.py:execute():126] 429 response executing GraphQL.
2021-03-14 00:11:58,148 ERROR   Thread-10 :1776 [internal_api.py:execute():127] {"error":"rate limit exceeded"}

2021-03-14 00:12:11,690 ERROR   Thread-10 :1776 [internal_api.py:execute():126] 429 response executing GraphQL.
2021-03-14 00:12:11,690 ERROR   Thread-10 :1776 [internal_api.py:execute():127] {"error":"rate limit exceeded"}

2021-03-14 00:12:13,266 ERROR   Thread-10 :1776 [internal_api.py:execute():126] 429 response executing GraphQL.
2021-03-14 00:12:13,267 ERROR   Thread-10 :1776 [internal_api.py:execute():127] {"error":"rate limit exceeded"}

2021-03-14 00:12:29,369 ERROR   Thread-10 :1776 [internal_api.py:execute():126] 429 response executing GraphQL.
2021-03-14 00:12:29,369 ERROR   Thread-10 :1776 [internal_api.py:execute():127] {"error":"rate limit exceeded"}

2021-03-14 00:12:40,974 ERROR   Thread-10 :1776 [internal_api.py:execute():126] 429 response executing GraphQL.
2021-03-14 00:12:40,976 ERROR   Thread-10 :1776 [internal_api.py:execute():127] {"error":"rate limit exceeded"}

2021-03-14 00:12:42,843 ERROR   Thread-10 :1776 [internal_api.py:execute():126] 429 response executing GraphQL.
2021-03-14 00:12:42,844 ERROR   Thread-10 :1776 [internal_api.py:execute():127] {"error":"rate limit exceeded"}

2021-03-14 00:12:59,034 ERROR   Thread-10 :1776 [internal_api.py:execute():126] 429 response executing GraphQL.
2021-03-14 00:12:59,035 ERROR   Thread-10 :1776 [internal_api.py:execute():127] {"error":"rate limit exceeded"}

2021-03-14 00:13:14,438 ERROR   Thread-10 :1776 [internal_api.py:execute():126] 429 response executing GraphQL.
2021-03-14 00:13:14,439 ERROR   Thread-10 :1776 [internal_api.py:execute():127] {"error":"rate limit exceeded"}

2021-03-14 00:13:25,558 ERROR   Thread-10 :1776 [internal_api.py:execute():126] 429 response executing GraphQL.
2021-03-14 00:13:25,560 ERROR   Thread-10 :1776 [internal_api.py:execute():127] {"error":"rate limit exceeded"}

2021-03-14 00:13:27,095 ERROR   Thread-10 :1776 [internal_api.py:execute():126] 429 response executing GraphQL.
2021-03-14 00:13:27,097 ERROR   Thread-10 :1776 [internal_api.py:execute():127] {"error":"rate limit exceeded"}

2021-03-14 00:13:29,773 ERROR   Thread-10 :1776 [internal_api.py:execute():126] 429 response executing GraphQL.
2021-03-14 00:13:29,775 ERROR   Thread-10 :1776 [internal_api.py:execute():127] {"error":"rate limit exceeded"}

2021-03-14 00:13:29,776 ERROR   Thread-10 :1776 [retry.py:__call__():111] Retry attempt failed:
Traceback (most recent call last):
  File "C:\Users\rigve\AppData\Roaming\Python\Python38\site-packages\wandb\old\retry.py", line 96, in __call__
    result = self._call_fn(*args, **kwargs)
  File "C:\Users\rigve\AppData\Roaming\Python\Python38\site-packages\wandb\sdk\internal\internal_api.py", line 129, in execute
    six.reraise(*sys.exc_info())
  File "C:\Users\rigve\AppData\Roaming\Python\Python38\site-packages\six.py", line 703, in reraise
    raise value
  File "C:\Users\rigve\AppData\Roaming\Python\Python38\site-packages\wandb\sdk\internal\internal_api.py", line 123, in execute
    return self.client.execute(*args, **kwargs)
  File "C:\Users\rigve\AppData\Roaming\Python\Python38\site-packages\wandb\vendor\gql-0.2.0\gql\client.py", line 52, in execute
    result = self._get_result(document, *args, **kwargs)
  File "C:\Users\rigve\AppData\Roaming\Python\Python38\site-packages\wandb\vendor\gql-0.2.0\gql\client.py", line 60, in _get_result
    return self.transport.execute(document, *args, **kwargs)
  File "C:\Users\rigve\AppData\Roaming\Python\Python38\site-packages\wandb\vendor\gql-0.2.0\gql\transport\requests.py", line 39, in execute
    request.raise_for_status()
  File "C:\Users\rigve\AppData\Roaming\Python\Python38\site-packages\requests\models.py", line 943, in raise_for_status
    raise HTTPError(http_error_msg, response=self)
requests.exceptions.HTTPError: 429 Client Error: Too Many Requests for url: https://api.wandb.ai/graphql
2021-03-14 00:13:44,095 ERROR   Thread-10 :1776 [internal_api.py:execute():126] 429 response executing GraphQL.
2021-03-14 00:13:44,096 ERROR   Thread-10 :1776 [internal_api.py:execute():127] {"error":"rate limit exceeded"}

2021-03-14 00:13:57,250 ERROR   Thread-10 :1776 [internal_api.py:execute():126] 429 response executing GraphQL.
2021-03-14 00:13:57,251 ERROR   Thread-10 :1776 [internal_api.py:execute():127] {"error":"rate limit exceeded"}

2021-03-14 00:13:58,704 ERROR   Thread-10 :1776 [internal_api.py:execute():126] 429 response executing GraphQL.
2021-03-14 00:13:58,705 ERROR   Thread-10 :1776 [internal_api.py:execute():127] {"error":"rate limit exceeded"}

2021-03-14 00:14:11,888 ERROR   Thread-10 :1776 [internal_api.py:execute():126] 429 response executing GraphQL.
2021-03-14 00:14:11,888 ERROR   Thread-10 :1776 [internal_api.py:execute():127] {"error":"rate limit exceeded"}

2021-03-14 00:14:13,603 ERROR   Thread-10 :1776 [internal_api.py:execute():126] 429 response executing GraphQL.
2021-03-14 00:14:13,605 ERROR   Thread-10 :1776 [internal_api.py:execute():127] {"error":"rate limit exceeded"}

2021-03-14 00:14:28,213 ERROR   Thread-10 :1776 [internal_api.py:execute():126] 429 response executing GraphQL.
2021-03-14 00:14:28,214 ERROR   Thread-10 :1776 [internal_api.py:execute():127] {"error":"rate limit exceeded"}

2021-03-14 00:14:29,829 ERROR   Thread-10 :1776 [internal_api.py:execute():126] 429 response executing GraphQL.
2021-03-14 00:14:29,830 ERROR   Thread-10 :1776 [internal_api.py:execute():127] {"error":"rate limit exceeded"}

2021-03-14 00:14:42,322 ERROR   Thread-10 :1776 [internal_api.py:execute():126] 429 response executing GraphQL.
2021-03-14 00:14:42,324 ERROR   Thread-10 :1776 [internal_api.py:execute():127] {"error":"rate limit exceeded"}

2021-03-14 00:14:43,898 ERROR   Thread-10 :1776 [internal_api.py:execute():126] 429 response executing GraphQL.
2021-03-14 00:14:43,898 ERROR   Thread-10 :1776 [internal_api.py:execute():127] {"error":"rate limit exceeded"}

2021-03-14 00:14:56,607 ERROR   Thread-10 :1776 [internal_api.py:execute():126] 429 response executing GraphQL.
2021-03-14 00:14:56,608 ERROR   Thread-10 :1776 [internal_api.py:execute():127] {"error":"rate limit exceeded"}

2021-03-14 00:14:58,261 ERROR   Thread-10 :1776 [internal_api.py:execute():126] 429 response executing GraphQL.
2021-03-14 00:14:58,261 ERROR   Thread-10 :1776 [internal_api.py:execute():127] {"error":"rate limit exceeded"}

2021-03-14 00:15:13,860 ERROR   Thread-10 :1776 [internal_api.py:execute():126] 429 response executing GraphQL.
2021-03-14 00:15:13,861 ERROR   Thread-10 :1776 [internal_api.py:execute():127] {"error":"rate limit exceeded"}

2021-03-14 00:15:28,828 ERROR   Thread-10 :1776 [internal_api.py:execute():126] 429 response executing GraphQL.
2021-03-14 00:15:28,829 ERROR   Thread-10 :1776 [internal_api.py:execute():127] {"error":"rate limit exceeded"}

2021-03-14 00:15:42,729 ERROR   Thread-10 :1776 [internal_api.py:execute():126] 429 response executing GraphQL.
2021-03-14 00:15:42,731 ERROR   Thread-10 :1776 [internal_api.py:execute():127] {"error":"rate limit exceeded"}

2021-03-14 00:15:44,220 ERROR   Thread-10 :1776 [internal_api.py:execute():126] 429 response executing GraphQL.
2021-03-14 00:15:44,221 ERROR   Thread-10 :1776 [internal_api.py:execute():127] {"error":"rate limit exceeded"}

2021-03-14 00:15:57,024 ERROR   Thread-10 :1776 [internal_api.py:execute():126] 429 response executing GraphQL.
2021-03-14 00:15:57,025 ERROR   Thread-10 :1776 [internal_api.py:execute():127] {"error":"rate limit exceeded"}

2021-03-14 00:15:58,766 ERROR   Thread-10 :1776 [internal_api.py:execute():126] 429 response executing GraphQL.
2021-03-14 00:15:58,767 ERROR   Thread-10 :1776 [internal_api.py:execute():127] {"error":"rate limit exceeded"}

2021-03-14 00:16:13,272 ERROR   Thread-10 :1776 [internal_api.py:execute():126] 429 response executing GraphQL.
2021-03-14 00:16:13,273 ERROR   Thread-10 :1776 [internal_api.py:execute():127] {"error":"rate limit exceeded"}

2021-03-14 00:16:14,937 ERROR   Thread-10 :1776 [internal_api.py:execute():126] 429 response executing GraphQL.
2021-03-14 00:16:14,938 ERROR   Thread-10 :1776 [internal_api.py:execute():127] {"error":"rate limit exceeded"}

2021-03-14 00:16:27,835 ERROR   Thread-10 :1776 [internal_api.py:execute():126] 429 response executing GraphQL.
2021-03-14 00:16:27,837 ERROR   Thread-10 :1776 [internal_api.py:execute():127] {"error":"rate limit exceeded"}

2021-03-14 00:16:29,419 ERROR   Thread-10 :1776 [internal_api.py:execute():126] 429 response executing GraphQL.
2021-03-14 00:16:29,421 ERROR   Thread-10 :1776 [internal_api.py:execute():127] {"error":"rate limit exceeded"}

2021-03-14 00:16:42,821 ERROR   Thread-10 :1776 [internal_api.py:execute():126] 429 response executing GraphQL.
2021-03-14 00:16:42,823 ERROR   Thread-10 :1776 [internal_api.py:execute():127] {"error":"rate limit exceeded"}

2021-03-14 00:16:44,478 ERROR   Thread-10 :1776 [internal_api.py:execute():126] 429 response executing GraphQL.
2021-03-14 00:16:44,479 ERROR   Thread-10 :1776 [internal_api.py:execute():127] {"error":"rate limit exceeded"}

2021-03-14 00:16:58,899 ERROR   Thread-10 :1776 [internal_api.py:execute():126] 429 response executing GraphQL.
2021-03-14 00:16:58,899 ERROR   Thread-10 :1776 [internal_api.py:execute():127] {"error":"rate limit exceeded"}

2021-03-14 00:17:12,850 ERROR   Thread-10 :1776 [internal_api.py:execute():126] 429 response executing GraphQL.
2021-03-14 00:17:12,850 ERROR   Thread-10 :1776 [internal_api.py:execute():127] {"error":"rate limit exceeded"}

2021-03-14 00:17:14,509 ERROR   Thread-10 :1776 [internal_api.py:execute():126] 429 response executing GraphQL.
2021-03-14 00:17:14,509 ERROR   Thread-10 :1776 [internal_api.py:execute():127] {"error":"rate limit exceeded"}

2021-03-14 00:17:27,360 ERROR   Thread-10 :1776 [internal_api.py:execute():126] 429 response executing GraphQL.
2021-03-14 00:17:27,361 ERROR   Thread-10 :1776 [internal_api.py:execute():127] {"error":"rate limit exceeded"}

2021-03-14 00:17:28,870 ERROR   Thread-10 :1776 [internal_api.py:execute():126] 429 response executing GraphQL.
2021-03-14 00:17:28,871 ERROR   Thread-10 :1776 [internal_api.py:execute():127] {"error":"rate limit exceeded"}

2021-03-14 00:17:41,888 ERROR   Thread-10 :1776 [internal_api.py:execute():126] 429 response executing GraphQL.
2021-03-14 00:17:41,888 ERROR   Thread-10 :1776 [internal_api.py:execute():127] {"error":"rate limit exceeded"}

2021-03-14 00:17:43,609 ERROR   Thread-10 :1776 [internal_api.py:execute():126] 429 response executing GraphQL.
2021-03-14 00:17:43,610 ERROR   Thread-10 :1776 [internal_api.py:execute():127] {"error":"rate limit exceeded"}

2021-03-14 00:17:58,683 ERROR   Thread-10 :1776 [internal_api.py:execute():126] 429 response executing GraphQL.
2021-03-14 00:17:58,684 ERROR   Thread-10 :1776 [internal_api.py:execute():127] {"error":"rate limit exceeded"}

2021-03-14 00:18:12,787 ERROR   Thread-10 :1776 [internal_api.py:execute():126] 429 response executing GraphQL.
2021-03-14 00:18:12,797 ERROR   Thread-10 :1776 [internal_api.py:execute():127] {"error":"rate limit exceeded"}

2021-03-14 00:18:14,345 ERROR   Thread-10 :1776 [internal_api.py:execute():126] 429 response executing GraphQL.
2021-03-14 00:18:14,345 ERROR   Thread-10 :1776 [internal_api.py:execute():127] {"error":"rate limit exceeded"}

2021-03-14 00:18:26,810 ERROR   Thread-10 :1776 [internal_api.py:execute():126] 429 response executing GraphQL.
2021-03-14 00:18:26,810 ERROR   Thread-10 :1776 [internal_api.py:execute():127] {"error":"rate limit exceeded"}

2021-03-14 00:18:28,479 ERROR   Thread-10 :1776 [internal_api.py:execute():126] 429 response executing GraphQL.
2021-03-14 00:18:28,480 ERROR   Thread-10 :1776 [internal_api.py:execute():127] {"error":"rate limit exceeded"}

2021-03-14 00:18:56,878 ERROR   Thread-10 :1776 [internal_api.py:execute():126] 429 response executing GraphQL.
2021-03-14 00:18:56,878 ERROR   Thread-10 :1776 [internal_api.py:execute():127] {"error":"rate limit exceeded"}

2021-03-14 00:18:58,684 ERROR   Thread-10 :1776 [internal_api.py:execute():126] 429 response executing GraphQL.
2021-03-14 00:18:58,685 ERROR   Thread-10 :1776 [internal_api.py:execute():127] {"error":"rate limit exceeded"}

2021-03-14 00:19:12,180 ERROR   Thread-10 :1776 [internal_api.py:execute():126] 429 response executing GraphQL.
2021-03-14 00:19:12,181 ERROR   Thread-10 :1776 [internal_api.py:execute():127] {"error":"rate limit exceeded"}

2021-03-14 00:19:13,655 ERROR   Thread-10 :1776 [internal_api.py:execute():126] 429 response executing GraphQL.
2021-03-14 00:19:13,655 ERROR   Thread-10 :1776 [internal_api.py:execute():127] {"error":"rate limit exceeded"}

2021-03-14 00:19:28,383 ERROR   Thread-10 :1776 [internal_api.py:execute():126] 429 response executing GraphQL.
2021-03-14 00:19:28,384 ERROR   Thread-10 :1776 [internal_api.py:execute():127] {"error":"rate limit exceeded"}

2021-03-14 00:19:29,983 ERROR   Thread-10 :1776 [internal_api.py:execute():126] 429 response executing GraphQL.
2021-03-14 00:19:29,983 ERROR   Thread-10 :1776 [internal_api.py:execute():127] {"error":"rate limit exceeded"}

2021-03-14 00:19:42,522 ERROR   Thread-10 :1776 [internal_api.py:execute():126] 429 response executing GraphQL.
2021-03-14 00:19:42,524 ERROR   Thread-10 :1776 [internal_api.py:execute():127] {"error":"rate limit exceeded"}

2021-03-14 00:19:44,211 ERROR   Thread-10 :1776 [internal_api.py:execute():126] 429 response executing GraphQL.
2021-03-14 00:19:44,213 ERROR   Thread-10 :1776 [internal_api.py:execute():127] {"error":"rate limit exceeded"}

2021-03-14 00:19:56,328 ERROR   Thread-10 :1776 [internal_api.py:execute():126] 429 response executing GraphQL.
2021-03-14 00:19:56,329 ERROR   Thread-10 :1776 [internal_api.py:execute():127] {"error":"rate limit exceeded"}

2021-03-14 00:19:58,013 ERROR   Thread-10 :1776 [internal_api.py:execute():126] 429 response executing GraphQL.
2021-03-14 00:19:58,014 ERROR   Thread-10 :1776 [internal_api.py:execute():127] {"error":"rate limit exceeded"}

2021-03-14 00:20:14,350 ERROR   Thread-10 :1776 [internal_api.py:execute():126] 429 response executing GraphQL.
2021-03-14 00:20:14,353 ERROR   Thread-10 :1776 [internal_api.py:execute():127] {"error":"rate limit exceeded"}

2021-03-14 00:20:29,624 ERROR   Thread-10 :1776 [internal_api.py:execute():126] 429 response executing GraphQL.
2021-03-14 00:20:29,625 ERROR   Thread-10 :1776 [internal_api.py:execute():127] {"error":"rate limit exceeded"}

2021-03-14 00:20:40,909 ERROR   Thread-10 :1776 [internal_api.py:execute():126] 429 response executing GraphQL.
2021-03-14 00:20:40,910 ERROR   Thread-10 :1776 [internal_api.py:execute():127] {"error":"rate limit exceeded"}

2021-03-14 00:20:42,453 ERROR   Thread-10 :1776 [internal_api.py:execute():126] 429 response executing GraphQL.
2021-03-14 00:20:42,455 ERROR   Thread-10 :1776 [internal_api.py:execute():127] {"error":"rate limit exceeded"}

2021-03-14 00:20:59,122 ERROR   Thread-10 :1776 [internal_api.py:execute():126] 429 response executing GraphQL.
2021-03-14 00:20:59,125 ERROR   Thread-10 :1776 [internal_api.py:execute():127] {"error":"rate limit exceeded"}

2021-03-14 00:21:11,636 ERROR   Thread-10 :1776 [internal_api.py:execute():126] 429 response executing GraphQL.
2021-03-14 00:21:11,639 ERROR   Thread-10 :1776 [internal_api.py:execute():127] {"error":"rate limit exceeded"}

2021-03-14 00:21:13,387 ERROR   Thread-10 :1776 [internal_api.py:execute():126] 429 response executing GraphQL.
2021-03-14 00:21:13,388 ERROR   Thread-10 :1776 [internal_api.py:execute():127] {"error":"rate limit exceeded"}

2021-03-14 00:21:42,189 ERROR   Thread-10 :1776 [internal_api.py:execute():126] 429 response executing GraphQL.
2021-03-14 00:21:42,190 ERROR   Thread-10 :1776 [internal_api.py:execute():127] {"error":"rate limit exceeded"}

2021-03-14 00:21:43,724 ERROR   Thread-10 :1776 [internal_api.py:execute():126] 429 response executing GraphQL.
2021-03-14 00:21:43,725 ERROR   Thread-10 :1776 [internal_api.py:execute():127] {"error":"rate limit exceeded"}

2021-03-14 00:21:56,957 ERROR   Thread-10 :1776 [internal_api.py:execute():126] 429 response executing GraphQL.
2021-03-14 00:21:56,958 ERROR   Thread-10 :1776 [internal_api.py:execute():127] {"error":"rate limit exceeded"}

2021-03-14 00:21:58,461 ERROR   Thread-10 :1776 [internal_api.py:execute():126] 429 response executing GraphQL.
2021-03-14 00:21:58,462 ERROR   Thread-10 :1776 [internal_api.py:execute():127] {"error":"rate limit exceeded"}

2021-03-14 00:22:12,073 ERROR   Thread-10 :1776 [internal_api.py:execute():126] 429 response executing GraphQL.
2021-03-14 00:22:12,074 ERROR   Thread-10 :1776 [internal_api.py:execute():127] {"error":"rate limit exceeded"}

2021-03-14 00:22:13,565 ERROR   Thread-10 :1776 [internal_api.py:execute():126] 429 response executing GraphQL.
2021-03-14 00:22:13,566 ERROR   Thread-10 :1776 [internal_api.py:execute():127] {"error":"rate limit exceeded"}

2021-03-14 00:22:27,566 ERROR   Thread-10 :1776 [internal_api.py:execute():126] 429 response executing GraphQL.
2021-03-14 00:22:27,567 ERROR   Thread-10 :1776 [internal_api.py:execute():127] {"error":"rate limit exceeded"}

2021-03-14 00:22:29,263 ERROR   Thread-10 :1776 [internal_api.py:execute():126] 429 response executing GraphQL.
2021-03-14 00:22:29,265 ERROR   Thread-10 :1776 [internal_api.py:execute():127] {"error":"rate limit exceeded"}

2021-03-14 00:22:41,195 ERROR   Thread-10 :1776 [internal_api.py:execute():126] 429 response executing GraphQL.
2021-03-14 00:22:41,207 ERROR   Thread-10 :1776 [internal_api.py:execute():127] {"error":"rate limit exceeded"}

2021-03-14 00:22:42,914 ERROR   Thread-10 :1776 [internal_api.py:execute():126] 429 response executing GraphQL.
2021-03-14 00:22:42,927 ERROR   Thread-10 :1776 [internal_api.py:execute():127] {"error":"rate limit exceeded"}

2021-03-14 00:22:59,943 ERROR   Thread-10 :1776 [internal_api.py:execute():126] 429 response executing GraphQL.
2021-03-14 00:22:59,954 ERROR   Thread-10 :1776 [internal_api.py:execute():127] {"error":"rate limit exceeded"}

2021-03-14 00:23:11,557 ERROR   Thread-10 :1776 [internal_api.py:execute():126] 429 response executing GraphQL.
2021-03-14 00:23:11,559 ERROR   Thread-10 :1776 [internal_api.py:execute():127] {"error":"rate limit exceeded"}

2021-03-14 00:23:13,125 ERROR   Thread-10 :1776 [internal_api.py:execute():126] 429 response executing GraphQL.
2021-03-14 00:23:13,126 ERROR   Thread-10 :1776 [internal_api.py:execute():127] {"error":"rate limit exceeded"}

2021-03-14 00:23:29,950 ERROR   Thread-10 :1776 [internal_api.py:execute():126] 429 response executing GraphQL.
2021-03-14 00:23:29,951 ERROR   Thread-10 :1776 [internal_api.py:execute():127] {"error":"rate limit exceeded"}

2021-03-14 00:23:41,676 ERROR   Thread-10 :1776 [internal_api.py:execute():126] 429 response executing GraphQL.
2021-03-14 00:23:41,677 ERROR   Thread-10 :1776 [internal_api.py:execute():127] {"error":"rate limit exceeded"}

2021-03-14 00:23:43,203 ERROR   Thread-10 :1776 [internal_api.py:execute():126] 429 response executing GraphQL.
2021-03-14 00:23:43,203 ERROR   Thread-10 :1776 [internal_api.py:execute():127] {"error":"rate limit exceeded"}

2021-03-14 00:23:59,598 ERROR   Thread-10 :1776 [internal_api.py:execute():126] 429 response executing GraphQL.
2021-03-14 00:23:59,598 ERROR   Thread-10 :1776 [internal_api.py:execute():127] {"error":"rate limit exceeded"}

2021-03-14 00:24:11,113 ERROR   Thread-10 :1776 [internal_api.py:execute():126] 429 response executing GraphQL.
2021-03-14 00:24:11,123 ERROR   Thread-10 :1776 [internal_api.py:execute():127] {"error":"rate limit exceeded"}

2021-03-14 00:24:12,775 ERROR   Thread-10 :1776 [internal_api.py:execute():126] 429 response executing GraphQL.
2021-03-14 00:24:12,776 ERROR   Thread-10 :1776 [internal_api.py:execute():127] {"error":"rate limit exceeded"}

2021-03-14 00:24:29,153 ERROR   Thread-10 :1776 [internal_api.py:execute():126] 429 response executing GraphQL.
2021-03-14 00:24:29,154 ERROR   Thread-10 :1776 [internal_api.py:execute():127] {"error":"rate limit exceeded"}

2021-03-14 00:24:41,969 ERROR   Thread-10 :1776 [internal_api.py:execute():126] 429 response executing GraphQL.
2021-03-14 00:24:41,970 ERROR   Thread-10 :1776 [internal_api.py:execute():127] {"error":"rate limit exceeded"}

2021-03-14 00:24:43,459 ERROR   Thread-10 :1776 [internal_api.py:execute():126] 429 response executing GraphQL.
2021-03-14 00:24:43,460 ERROR   Thread-10 :1776 [internal_api.py:execute():127] {"error":"rate limit exceeded"}

2021-03-14 00:24:55,913 ERROR   Thread-10 :1776 [internal_api.py:execute():126] 429 response executing GraphQL.
2021-03-14 00:24:55,914 ERROR   Thread-10 :1776 [internal_api.py:execute():127] {"error":"rate limit exceeded"}

2021-03-14 00:24:57,609 ERROR   Thread-10 :1776 [internal_api.py:execute():126] 429 response executing GraphQL.
2021-03-14 00:24:57,611 ERROR   Thread-10 :1776 [internal_api.py:execute():127] {"error":"rate limit exceeded"}

2021-03-14 00:25:14,739 ERROR   Thread-10 :1776 [internal_api.py:execute():126] 429 response executing GraphQL.
2021-03-14 00:25:14,740 ERROR   Thread-10 :1776 [internal_api.py:execute():127] {"error":"rate limit exceeded"}

2021-03-14 00:25:26,254 ERROR   Thread-10 :1776 [internal_api.py:execute():126] 429 response executing GraphQL.
2021-03-14 00:25:26,255 ERROR   Thread-10 :1776 [internal_api.py:execute():127] {"error":"rate limit exceeded"}

2021-03-14 00:25:27,944 ERROR   Thread-10 :1776 [internal_api.py:execute():126] 429 response executing GraphQL.
2021-03-14 00:25:27,945 ERROR   Thread-10 :1776 [internal_api.py:execute():127] {"error":"rate limit exceeded"}

2021-03-14 00:25:44,769 ERROR   Thread-10 :1776 [internal_api.py:execute():126] 429 response executing GraphQL.
2021-03-14 00:25:44,770 ERROR   Thread-10 :1776 [internal_api.py:execute():127] {"error":"rate limit exceeded"}

2021-03-14 00:25:56,852 ERROR   Thread-10 :1776 [internal_api.py:execute():126] 429 response executing GraphQL.
2021-03-14 00:25:56,852 ERROR   Thread-10 :1776 [internal_api.py:execute():127] {"error":"rate limit exceeded"}

2021-03-14 00:25:58,304 ERROR   Thread-10 :1776 [internal_api.py:execute():126] 429 response executing GraphQL.
2021-03-14 00:25:58,304 ERROR   Thread-10 :1776 [internal_api.py:execute():127] {"error":"rate limit exceeded"}

2021-03-14 00:26:13,787 ERROR   Thread-10 :1776 [internal_api.py:execute():126] 429 response executing GraphQL.
2021-03-14 00:26:13,788 ERROR   Thread-10 :1776 [internal_api.py:execute():127] {"error":"rate limit exceeded"}

2021-03-14 00:26:28,105 ERROR   Thread-10 :1776 [internal_api.py:execute():126] 429 response executing GraphQL.
2021-03-14 00:26:28,105 ERROR   Thread-10 :1776 [internal_api.py:execute():127] {"error":"rate limit exceeded"}

2021-03-14 00:26:29,612 ERROR   Thread-10 :1776 [internal_api.py:execute():126] 429 response executing GraphQL.
2021-03-14 00:26:29,613 ERROR   Thread-10 :1776 [internal_api.py:execute():127] {"error":"rate limit exceeded"}

2021-03-14 00:26:42,248 ERROR   Thread-10 :1776 [internal_api.py:execute():126] 429 response executing GraphQL.
2021-03-14 00:26:42,249 ERROR   Thread-10 :1776 [internal_api.py:execute():127] {"error":"rate limit exceeded"}

2021-03-14 00:26:43,710 ERROR   Thread-10 :1776 [internal_api.py:execute():126] 429 response executing GraphQL.
2021-03-14 00:26:43,710 ERROR   Thread-10 :1776 [internal_api.py:execute():127] {"error":"rate limit exceeded"}

2021-03-14 00:26:57,254 ERROR   Thread-10 :1776 [internal_api.py:execute():126] 429 response executing GraphQL.
2021-03-14 00:26:57,255 ERROR   Thread-10 :1776 [internal_api.py:execute():127] {"error":"rate limit exceeded"}

2021-03-14 00:26:58,691 ERROR   Thread-10 :1776 [internal_api.py:execute():126] 429 response executing GraphQL.
2021-03-14 00:26:58,691 ERROR   Thread-10 :1776 [internal_api.py:execute():127] {"error":"rate limit exceeded"}

2021-03-14 00:27:12,551 ERROR   Thread-10 :1776 [internal_api.py:execute():126] 429 response executing GraphQL.
2021-03-14 00:27:12,551 ERROR   Thread-10 :1776 [internal_api.py:execute():127] {"error":"rate limit exceeded"}

2021-03-14 00:27:14,248 ERROR   Thread-10 :1776 [internal_api.py:execute():126] 429 response executing GraphQL.
2021-03-14 00:27:14,249 ERROR   Thread-10 :1776 [internal_api.py:execute():127] {"error":"rate limit exceeded"}

2021-03-14 00:27:27,072 ERROR   Thread-10 :1776 [internal_api.py:execute():126] 429 response executing GraphQL.
2021-03-14 00:27:27,074 ERROR   Thread-10 :1776 [internal_api.py:execute():127] {"error":"rate limit exceeded"}

2021-03-14 00:27:28,652 ERROR   Thread-10 :1776 [internal_api.py:execute():126] 429 response executing GraphQL.
2021-03-14 00:27:28,653 ERROR   Thread-10 :1776 [internal_api.py:execute():127] {"error":"rate limit exceeded"}

2021-03-14 00:27:44,580 ERROR   Thread-10 :1776 [internal_api.py:execute():126] 429 response executing GraphQL.
2021-03-14 00:27:44,580 ERROR   Thread-10 :1776 [internal_api.py:execute():127] {"error":"rate limit exceeded"}

2021-03-14 00:27:56,437 ERROR   Thread-10 :1776 [internal_api.py:execute():126] 429 response executing GraphQL.
2021-03-14 00:27:56,438 ERROR   Thread-10 :1776 [internal_api.py:execute():127] {"error":"rate limit exceeded"}

2021-03-14 00:27:57,955 ERROR   Thread-10 :1776 [internal_api.py:execute():126] 429 response executing GraphQL.
2021-03-14 00:27:57,955 ERROR   Thread-10 :1776 [internal_api.py:execute():127] {"error":"rate limit exceeded"}

2021-03-14 00:28:14,575 ERROR   Thread-10 :1776 [internal_api.py:execute():126] 429 response executing GraphQL.
2021-03-14 00:28:14,576 ERROR   Thread-10 :1776 [internal_api.py:execute():127] {"error":"rate limit exceeded"}

2021-03-14 00:28:26,000 ERROR   Thread-10 :1776 [internal_api.py:execute():126] 429 response executing GraphQL.
2021-03-14 00:28:26,000 ERROR   Thread-10 :1776 [internal_api.py:execute():127] {"error":"rate limit exceeded"}

2021-03-14 00:28:27,702 ERROR   Thread-10 :1776 [internal_api.py:execute():126] 429 response executing GraphQL.
2021-03-14 00:28:27,704 ERROR   Thread-10 :1776 [internal_api.py:execute():127] {"error":"rate limit exceeded"}

2021-03-14 00:28:44,799 ERROR   Thread-10 :1776 [internal_api.py:execute():126] 429 response executing GraphQL.
2021-03-14 00:28:44,800 ERROR   Thread-10 :1776 [internal_api.py:execute():127] {"error":"rate limit exceeded"}

2021-03-14 00:28:56,843 ERROR   Thread-10 :1776 [internal_api.py:execute():126] 429 response executing GraphQL.
2021-03-14 00:28:56,844 ERROR   Thread-10 :1776 [internal_api.py:execute():127] {"error":"rate limit exceeded"}

2021-03-14 00:28:58,377 ERROR   Thread-10 :1776 [internal_api.py:execute():126] 429 response executing GraphQL.
2021-03-14 00:28:58,377 ERROR   Thread-10 :1776 [internal_api.py:execute():127] {"error":"rate limit exceeded"}

2021-03-14 00:29:13,561 ERROR   Thread-10 :1776 [internal_api.py:execute():126] 429 response executing GraphQL.
2021-03-14 00:29:13,562 ERROR   Thread-10 :1776 [internal_api.py:execute():127] {"error":"rate limit exceeded"}

2021-03-14 00:29:28,537 ERROR   Thread-10 :1776 [internal_api.py:execute():126] 429 response executing GraphQL.
2021-03-14 00:29:28,538 ERROR   Thread-10 :1776 [internal_api.py:execute():127] {"error":"rate limit exceeded"}

2021-03-14 00:29:42,493 ERROR   Thread-10 :1776 [internal_api.py:execute():126] 429 response executing GraphQL.
2021-03-14 00:29:42,494 ERROR   Thread-10 :1776 [internal_api.py:execute():127] {"error":"rate limit exceeded"}

2021-03-14 00:29:43,947 ERROR   Thread-10 :1776 [internal_api.py:execute():126] 429 response executing GraphQL.
2021-03-14 00:29:43,948 ERROR   Thread-10 :1776 [internal_api.py:execute():127] {"error":"rate limit exceeded"}

2021-03-14 00:29:56,621 ERROR   Thread-10 :1776 [internal_api.py:execute():126] 429 response executing GraphQL.
2021-03-14 00:29:56,622 ERROR   Thread-10 :1776 [internal_api.py:execute():127] {"error":"rate limit exceeded"}

2021-03-14 00:29:58,131 ERROR   Thread-10 :1776 [internal_api.py:execute():126] 429 response executing GraphQL.
2021-03-14 00:29:58,132 ERROR   Thread-10 :1776 [internal_api.py:execute():127] {"error":"rate limit exceeded"}

2021-03-14 00:30:14,968 ERROR   Thread-10 :1776 [internal_api.py:execute():126] 429 response executing GraphQL.
2021-03-14 00:30:14,969 ERROR   Thread-10 :1776 [internal_api.py:execute():127] {"error":"rate limit exceeded"}

2021-03-14 00:30:26,873 ERROR   Thread-10 :1776 [internal_api.py:execute():126] 429 response executing GraphQL.
2021-03-14 00:30:26,874 ERROR   Thread-10 :1776 [internal_api.py:execute():127] {"error":"rate limit exceeded"}

2021-03-14 00:30:28,385 ERROR   Thread-10 :1776 [internal_api.py:execute():126] 429 response executing GraphQL.
2021-03-14 00:30:28,386 ERROR   Thread-10 :1776 [internal_api.py:execute():127] {"error":"rate limit exceeded"}

2021-03-14 00:30:41,227 ERROR   Thread-10 :1776 [internal_api.py:execute():126] 429 response executing GraphQL.
2021-03-14 00:30:41,229 ERROR   Thread-10 :1776 [internal_api.py:execute():127] {"error":"rate limit exceeded"}

2021-03-14 00:30:42,903 ERROR   Thread-10 :1776 [internal_api.py:execute():126] 429 response executing GraphQL.
2021-03-14 00:30:42,904 ERROR   Thread-10 :1776 [internal_api.py:execute():127] {"error":"rate limit exceeded"}

2021-03-14 00:30:59,016 ERROR   Thread-10 :1776 [internal_api.py:execute():126] 429 response executing GraphQL.
2021-03-14 00:30:59,018 ERROR   Thread-10 :1776 [internal_api.py:execute():127] {"error":"rate limit exceeded"}

2021-03-14 00:31:14,261 ERROR   Thread-10 :1776 [internal_api.py:execute():126] 429 response executing GraphQL.
2021-03-14 00:31:14,263 ERROR   Thread-10 :1776 [internal_api.py:execute():127] {"error":"rate limit exceeded"}

2021-03-14 00:31:28,510 ERROR   Thread-10 :1776 [internal_api.py:execute():126] 429 response executing GraphQL.
2021-03-14 00:31:28,512 ERROR   Thread-10 :1776 [internal_api.py:execute():127] {"error":"rate limit exceeded"}

2021-03-14 00:31:30,017 ERROR   Thread-10 :1776 [internal_api.py:execute():126] 429 response executing GraphQL.
2021-03-14 00:31:30,019 ERROR   Thread-10 :1776 [internal_api.py:execute():127] {"error":"rate limit exceeded"}

2021-03-14 00:31:42,777 ERROR   Thread-10 :1776 [internal_api.py:execute():126] 429 response executing GraphQL.
2021-03-14 00:31:42,777 ERROR   Thread-10 :1776 [internal_api.py:execute():127] {"error":"rate limit exceeded"}

2021-03-14 00:31:44,415 ERROR   Thread-10 :1776 [internal_api.py:execute():126] 429 response executing GraphQL.
2021-03-14 00:31:44,416 ERROR   Thread-10 :1776 [internal_api.py:execute():127] {"error":"rate limit exceeded"}

2021-03-14 00:31:57,344 ERROR   Thread-10 :1776 [internal_api.py:execute():126] 429 response executing GraphQL.
2021-03-14 00:31:57,345 ERROR   Thread-10 :1776 [internal_api.py:execute():127] {"error":"rate limit exceeded"}

2021-03-14 00:31:58,871 ERROR   Thread-10 :1776 [internal_api.py:execute():126] 429 response executing GraphQL.
2021-03-14 00:31:58,872 ERROR   Thread-10 :1776 [internal_api.py:execute():127] {"error":"rate limit exceeded"}

2021-03-14 00:32:11,894 ERROR   Thread-10 :1776 [internal_api.py:execute():126] 429 response executing GraphQL.
2021-03-14 00:32:11,895 ERROR   Thread-10 :1776 [internal_api.py:execute():127] {"error":"rate limit exceeded"}

2021-03-14 00:32:13,556 ERROR   Thread-10 :1776 [internal_api.py:execute():126] 429 response executing GraphQL.
2021-03-14 00:32:13,557 ERROR   Thread-10 :1776 [internal_api.py:execute():127] {"error":"rate limit exceeded"}

2021-03-14 00:32:30,150 ERROR   Thread-10 :1776 [internal_api.py:execute():126] 429 response executing GraphQL.
2021-03-14 00:32:30,150 ERROR   Thread-10 :1776 [internal_api.py:execute():127] {"error":"rate limit exceeded"}

2021-03-14 00:32:43,612 ERROR   Thread-10 :1776 [internal_api.py:execute():126] 429 response executing GraphQL.
2021-03-14 00:32:43,624 ERROR   Thread-10 :1776 [internal_api.py:execute():127] {"error":"rate limit exceeded"}

2021-03-14 00:32:57,615 ERROR   Thread-10 :1776 [internal_api.py:execute():126] 429 response executing GraphQL.
2021-03-14 00:32:57,616 ERROR   Thread-10 :1776 [internal_api.py:execute():127] {"error":"rate limit exceeded"}

2021-03-14 00:32:59,360 ERROR   Thread-10 :1776 [internal_api.py:execute():126] 429 response executing GraphQL.
2021-03-14 00:32:59,361 ERROR   Thread-10 :1776 [internal_api.py:execute():127] {"error":"rate limit exceeded"}

2021-03-14 00:33:11,076 ERROR   Thread-10 :1776 [internal_api.py:execute():126] 429 response executing GraphQL.
2021-03-14 00:33:11,076 ERROR   Thread-10 :1776 [internal_api.py:execute():127] {"error":"rate limit exceeded"}

2021-03-14 00:33:12,625 ERROR   Thread-10 :1776 [internal_api.py:execute():126] 429 response executing GraphQL.
2021-03-14 00:33:12,625 ERROR   Thread-10 :1776 [internal_api.py:execute():127] {"error":"rate limit exceeded"}

2021-03-14 00:33:29,687 ERROR   Thread-10 :1776 [internal_api.py:execute():126] 429 response executing GraphQL.
2021-03-14 00:33:29,688 ERROR   Thread-10 :1776 [internal_api.py:execute():127] {"error":"rate limit exceeded"}

2021-03-14 00:33:41,433 ERROR   Thread-10 :1776 [internal_api.py:execute():126] 429 response executing GraphQL.
2021-03-14 00:33:41,434 ERROR   Thread-10 :1776 [internal_api.py:execute():127] {"error":"rate limit exceeded"}

2021-03-14 00:33:42,936 ERROR   Thread-10 :1776 [internal_api.py:execute():126] 429 response executing GraphQL.
2021-03-14 00:33:42,936 ERROR   Thread-10 :1776 [internal_api.py:execute():127] {"error":"rate limit exceeded"}

2021-03-14 00:33:59,176 ERROR   Thread-10 :1776 [internal_api.py:execute():126] 429 response executing GraphQL.
2021-03-14 00:33:59,176 ERROR   Thread-10 :1776 [internal_api.py:execute():127] {"error":"rate limit exceeded"}

2021-03-14 00:34:11,848 ERROR   Thread-10 :1776 [internal_api.py:execute():126] 429 response executing GraphQL.
2021-03-14 00:34:11,848 ERROR   Thread-10 :1776 [internal_api.py:execute():127] {"error":"rate limit exceeded"}

2021-03-14 00:34:13,391 ERROR   Thread-10 :1776 [internal_api.py:execute():126] 429 response executing GraphQL.
2021-03-14 00:34:13,391 ERROR   Thread-10 :1776 [internal_api.py:execute():127] {"error":"rate limit exceeded"}

2021-03-14 00:34:26,808 ERROR   Thread-10 :1776 [internal_api.py:execute():126] 429 response executing GraphQL.
2021-03-14 00:34:26,808 ERROR   Thread-10 :1776 [internal_api.py:execute():127] {"error":"rate limit exceeded"}

2021-03-14 00:34:28,259 ERROR   Thread-10 :1776 [internal_api.py:execute():126] 429 response executing GraphQL.
2021-03-14 00:34:28,260 ERROR   Thread-10 :1776 [internal_api.py:execute():127] {"error":"rate limit exceeded"}

2021-03-14 00:34:41,941 ERROR   Thread-10 :1776 [internal_api.py:execute():126] 429 response executing GraphQL.
2021-03-14 00:34:41,941 ERROR   Thread-10 :1776 [internal_api.py:execute():127] {"error":"rate limit exceeded"}

2021-03-14 00:34:43,757 ERROR   Thread-10 :1776 [internal_api.py:execute():126] 429 response executing GraphQL.
2021-03-14 00:34:43,757 ERROR   Thread-10 :1776 [internal_api.py:execute():127] {"error":"rate limit exceeded"}

2021-03-14 00:34:57,109 ERROR   Thread-10 :1776 [internal_api.py:execute():126] 429 response executing GraphQL.
2021-03-14 00:34:57,110 ERROR   Thread-10 :1776 [internal_api.py:execute():127] {"error":"rate limit exceeded"}

2021-03-14 00:34:58,817 ERROR   Thread-10 :1776 [internal_api.py:execute():126] 429 response executing GraphQL.
2021-03-14 00:34:58,817 ERROR   Thread-10 :1776 [internal_api.py:execute():127] {"error":"rate limit exceeded"}

2021-03-14 00:35:11,799 ERROR   Thread-10 :1776 [internal_api.py:execute():126] 429 response executing GraphQL.
2021-03-14 00:35:11,800 ERROR   Thread-10 :1776 [internal_api.py:execute():127] {"error":"rate limit exceeded"}

2021-03-14 00:35:13,385 ERROR   Thread-10 :1776 [internal_api.py:execute():126] 429 response executing GraphQL.
2021-03-14 00:35:13,389 ERROR   Thread-10 :1776 [internal_api.py:execute():127] {"error":"rate limit exceeded"}

2021-03-14 00:35:41,245 ERROR   Thread-10 :1776 [internal_api.py:execute():126] 429 response executing GraphQL.
2021-03-14 00:35:41,245 ERROR   Thread-10 :1776 [internal_api.py:execute():127] {"error":"rate limit exceeded"}

2021-03-14 00:35:42,982 ERROR   Thread-10 :1776 [internal_api.py:execute():126] 429 response executing GraphQL.
2021-03-14 00:35:42,995 ERROR   Thread-10 :1776 [internal_api.py:execute():127] {"error":"rate limit exceeded"}

2021-03-14 00:35:59,280 ERROR   Thread-10 :1776 [internal_api.py:execute():126] 429 response executing GraphQL.
2021-03-14 00:35:59,280 ERROR   Thread-10 :1776 [internal_api.py:execute():127] {"error":"rate limit exceeded"}

2021-03-14 00:36:11,847 ERROR   Thread-10 :1776 [internal_api.py:execute():126] 429 response executing GraphQL.
2021-03-14 00:36:11,848 ERROR   Thread-10 :1776 [internal_api.py:execute():127] {"error":"rate limit exceeded"}

2021-03-14 00:36:13,352 ERROR   Thread-10 :1776 [internal_api.py:execute():126] 429 response executing GraphQL.
2021-03-14 00:36:13,352 ERROR   Thread-10 :1776 [internal_api.py:execute():127] {"error":"rate limit exceeded"}

2021-03-14 00:36:43,327 ERROR   Thread-10 :1776 [internal_api.py:execute():126] 429 response executing GraphQL.
2021-03-14 00:36:43,328 ERROR   Thread-10 :1776 [internal_api.py:execute():127] {"error":"rate limit exceeded"}

2021-03-14 00:36:44,935 ERROR   Thread-10 :1776 [internal_api.py:execute():126] 429 response executing GraphQL.
2021-03-14 00:36:44,935 ERROR   Thread-10 :1776 [internal_api.py:execute():127] {"error":"rate limit exceeded"}

2021-03-14 00:36:59,194 ERROR   Thread-10 :1776 [internal_api.py:execute():126] 429 response executing GraphQL.
2021-03-14 00:36:59,195 ERROR   Thread-10 :1776 [internal_api.py:execute():127] {"error":"rate limit exceeded"}

2021-03-14 00:37:12,142 ERROR   Thread-10 :1776 [internal_api.py:execute():126] 429 response executing GraphQL.
2021-03-14 00:37:12,142 ERROR   Thread-10 :1776 [internal_api.py:execute():127] {"error":"rate limit exceeded"}

2021-03-14 00:37:13,627 ERROR   Thread-10 :1776 [internal_api.py:execute():126] 429 response executing GraphQL.
2021-03-14 00:37:13,627 ERROR   Thread-10 :1776 [internal_api.py:execute():127] {"error":"rate limit exceeded"}

2021-03-14 00:37:25,788 ERROR   Thread-10 :1776 [internal_api.py:execute():126] 429 response executing GraphQL.
2021-03-14 00:37:25,789 ERROR   Thread-10 :1776 [internal_api.py:execute():127] {"error":"rate limit exceeded"}

2021-03-14 00:37:27,231 ERROR   Thread-10 :1776 [internal_api.py:execute():126] 429 response executing GraphQL.
2021-03-14 00:37:27,231 ERROR   Thread-10 :1776 [internal_api.py:execute():127] {"error":"rate limit exceeded"}

2021-03-14 00:37:44,012 ERROR   Thread-10 :1776 [internal_api.py:execute():126] 429 response executing GraphQL.
2021-03-14 00:37:44,012 ERROR   Thread-10 :1776 [internal_api.py:execute():127] {"error":"rate limit exceeded"}

2021-03-14 00:37:57,243 ERROR   Thread-10 :1776 [internal_api.py:execute():126] 429 response executing GraphQL.
2021-03-14 00:37:57,244 ERROR   Thread-10 :1776 [internal_api.py:execute():127] {"error":"rate limit exceeded"}

2021-03-14 00:37:58,830 ERROR   Thread-10 :1776 [internal_api.py:execute():126] 429 response executing GraphQL.
2021-03-14 00:37:58,831 ERROR   Thread-10 :1776 [internal_api.py:execute():127] {"error":"rate limit exceeded"}

2021-03-14 00:38:12,383 ERROR   Thread-10 :1776 [internal_api.py:execute():126] 429 response executing GraphQL.
2021-03-14 00:38:12,383 ERROR   Thread-10 :1776 [internal_api.py:execute():127] {"error":"rate limit exceeded"}

2021-03-14 00:38:13,993 ERROR   Thread-10 :1776 [internal_api.py:execute():126] 429 response executing GraphQL.
2021-03-14 00:38:13,994 ERROR   Thread-10 :1776 [internal_api.py:execute():127] {"error":"rate limit exceeded"}

2021-03-14 00:38:25,672 ERROR   Thread-10 :1776 [internal_api.py:execute():126] 429 response executing GraphQL.
2021-03-14 00:38:25,673 ERROR   Thread-10 :1776 [internal_api.py:execute():127] {"error":"rate limit exceeded"}

2021-03-14 00:38:27,244 ERROR   Thread-10 :1776 [internal_api.py:execute():126] 429 response executing GraphQL.
2021-03-14 00:38:27,245 ERROR   Thread-10 :1776 [internal_api.py:execute():127] {"error":"rate limit exceeded"}

2021-03-14 00:38:44,183 ERROR   Thread-10 :1776 [internal_api.py:execute():126] 429 response executing GraphQL.
2021-03-14 00:38:44,183 ERROR   Thread-10 :1776 [internal_api.py:execute():127] {"error":"rate limit exceeded"}

2021-03-14 00:38:56,201 ERROR   Thread-10 :1776 [internal_api.py:execute():126] 429 response executing GraphQL.
2021-03-14 00:38:56,202 ERROR   Thread-10 :1776 [internal_api.py:execute():127] {"error":"rate limit exceeded"}

2021-03-14 00:38:57,852 ERROR   Thread-10 :1776 [internal_api.py:execute():126] 429 response executing GraphQL.
2021-03-14 00:38:57,853 ERROR   Thread-10 :1776 [internal_api.py:execute():127] {"error":"rate limit exceeded"}

2021-03-14 00:39:13,901 ERROR   Thread-10 :1776 [internal_api.py:execute():126] 429 response executing GraphQL.
2021-03-14 00:39:13,903 ERROR   Thread-10 :1776 [internal_api.py:execute():127] {"error":"rate limit exceeded"}

2021-03-14 00:39:27,103 ERROR   Thread-10 :1776 [internal_api.py:execute():126] 429 response executing GraphQL.
2021-03-14 00:39:27,103 ERROR   Thread-10 :1776 [internal_api.py:execute():127] {"error":"rate limit exceeded"}

2021-03-14 00:39:29,236 ERROR   Thread-10 :1776 [internal_api.py:execute():126] 429 response executing GraphQL.
2021-03-14 00:39:29,237 ERROR   Thread-10 :1776 [internal_api.py:execute():127] {"error":"rate limit exceeded"}

2021-03-14 00:39:40,568 ERROR   Thread-10 :1776 [internal_api.py:execute():126] 429 response executing GraphQL.
2021-03-14 00:39:40,569 ERROR   Thread-10 :1776 [internal_api.py:execute():127] {"error":"rate limit exceeded"}

2021-03-14 00:39:42,070 ERROR   Thread-10 :1776 [internal_api.py:execute():126] 429 response executing GraphQL.
2021-03-14 00:39:42,074 ERROR   Thread-10 :1776 [internal_api.py:execute():127] {"error":"rate limit exceeded"}

2021-03-14 00:39:44,713 ERROR   Thread-10 :1776 [internal_api.py:execute():126] 429 response executing GraphQL.
2021-03-14 00:39:44,715 ERROR   Thread-10 :1776 [internal_api.py:execute():127] {"error":"rate limit exceeded"}

2021-03-14 00:39:44,715 ERROR   Thread-10 :1776 [retry.py:__call__():111] Retry attempt failed:
Traceback (most recent call last):
  File "C:\Users\rigve\AppData\Roaming\Python\Python38\site-packages\wandb\old\retry.py", line 96, in __call__
    result = self._call_fn(*args, **kwargs)
  File "C:\Users\rigve\AppData\Roaming\Python\Python38\site-packages\wandb\sdk\internal\internal_api.py", line 129, in execute
    six.reraise(*sys.exc_info())
  File "C:\Users\rigve\AppData\Roaming\Python\Python38\site-packages\six.py", line 703, in reraise
    raise value
  File "C:\Users\rigve\AppData\Roaming\Python\Python38\site-packages\wandb\sdk\internal\internal_api.py", line 123, in execute
    return self.client.execute(*args, **kwargs)
  File "C:\Users\rigve\AppData\Roaming\Python\Python38\site-packages\wandb\vendor\gql-0.2.0\gql\client.py", line 52, in execute
    result = self._get_result(document, *args, **kwargs)
  File "C:\Users\rigve\AppData\Roaming\Python\Python38\site-packages\wandb\vendor\gql-0.2.0\gql\client.py", line 60, in _get_result
    return self.transport.execute(document, *args, **kwargs)
  File "C:\Users\rigve\AppData\Roaming\Python\Python38\site-packages\wandb\vendor\gql-0.2.0\gql\transport\requests.py", line 39, in execute
    request.raise_for_status()
  File "C:\Users\rigve\AppData\Roaming\Python\Python38\site-packages\requests\models.py", line 943, in raise_for_status
    raise HTTPError(http_error_msg, response=self)
requests.exceptions.HTTPError: 429 Client Error: Too Many Requests for url: https://api.wandb.ai/graphql
2021-03-14 00:39:58,634 ERROR   Thread-10 :1776 [internal_api.py:execute():126] 429 response executing GraphQL.
2021-03-14 00:39:58,642 ERROR   Thread-10 :1776 [internal_api.py:execute():127] {"error":"rate limit exceeded"}

2021-03-14 00:40:12,630 ERROR   Thread-10 :1776 [internal_api.py:execute():126] 429 response executing GraphQL.
2021-03-14 00:40:12,631 ERROR   Thread-10 :1776 [internal_api.py:execute():127] {"error":"rate limit exceeded"}

2021-03-14 00:40:14,352 ERROR   Thread-10 :1776 [internal_api.py:execute():126] 429 response executing GraphQL.
2021-03-14 00:40:14,352 ERROR   Thread-10 :1776 [internal_api.py:execute():127] {"error":"rate limit exceeded"}

2021-03-14 00:40:26,256 ERROR   Thread-10 :1776 [internal_api.py:execute():126] 429 response executing GraphQL.
2021-03-14 00:40:26,257 ERROR   Thread-10 :1776 [internal_api.py:execute():127] {"error":"rate limit exceeded"}

2021-03-14 00:40:27,942 ERROR   Thread-10 :1776 [internal_api.py:execute():126] 429 response executing GraphQL.
2021-03-14 00:40:27,945 ERROR   Thread-10 :1776 [internal_api.py:execute():127] {"error":"rate limit exceeded"}

2021-03-14 00:40:44,352 ERROR   Thread-10 :1776 [internal_api.py:execute():126] 429 response executing GraphQL.
2021-03-14 00:40:44,353 ERROR   Thread-10 :1776 [internal_api.py:execute():127] {"error":"rate limit exceeded"}

2021-03-14 00:40:56,154 ERROR   Thread-10 :1776 [internal_api.py:execute():126] 429 response executing GraphQL.
2021-03-14 00:40:56,154 ERROR   Thread-10 :1776 [internal_api.py:execute():127] {"error":"rate limit exceeded"}

2021-03-14 00:40:57,891 ERROR   Thread-10 :1776 [internal_api.py:execute():126] 429 response executing GraphQL.
2021-03-14 00:40:57,892 ERROR   Thread-10 :1776 [internal_api.py:execute():127] {"error":"rate limit exceeded"}

2021-03-14 00:41:14,108 ERROR   Thread-10 :1776 [internal_api.py:execute():126] 429 response executing GraphQL.
2021-03-14 00:41:14,109 ERROR   Thread-10 :1776 [internal_api.py:execute():127] {"error":"rate limit exceeded"}

2021-03-14 00:41:26,315 ERROR   Thread-10 :1776 [internal_api.py:execute():126] 429 response executing GraphQL.
2021-03-14 00:41:26,315 ERROR   Thread-10 :1776 [internal_api.py:execute():127] {"error":"rate limit exceeded"}

2021-03-14 00:41:27,977 ERROR   Thread-10 :1776 [internal_api.py:execute():126] 429 response executing GraphQL.
2021-03-14 00:41:27,978 ERROR   Thread-10 :1776 [internal_api.py:execute():127] {"error":"rate limit exceeded"}

2021-03-14 00:41:44,299 ERROR   Thread-10 :1776 [internal_api.py:execute():126] 429 response executing GraphQL.
2021-03-14 00:41:44,299 ERROR   Thread-10 :1776 [internal_api.py:execute():127] {"error":"rate limit exceeded"}

2021-03-14 00:41:56,179 ERROR   Thread-10 :1776 [internal_api.py:execute():126] 429 response executing GraphQL.
2021-03-14 00:41:56,179 ERROR   Thread-10 :1776 [internal_api.py:execute():127] {"error":"rate limit exceeded"}

2021-03-14 00:41:57,717 ERROR   Thread-10 :1776 [internal_api.py:execute():126] 429 response executing GraphQL.
2021-03-14 00:41:57,719 ERROR   Thread-10 :1776 [internal_api.py:execute():127] {"error":"rate limit exceeded"}

2021-03-14 00:42:14,039 ERROR   Thread-10 :1776 [internal_api.py:execute():126] 429 response executing GraphQL.
2021-03-14 00:42:14,040 ERROR   Thread-10 :1776 [internal_api.py:execute():127] {"error":"rate limit exceeded"}

2021-03-14 00:42:26,903 ERROR   Thread-10 :1776 [internal_api.py:execute():126] 429 response executing GraphQL.
2021-03-14 00:42:26,904 ERROR   Thread-10 :1776 [internal_api.py:execute():127] {"error":"rate limit exceeded"}

2021-03-14 00:42:28,782 ERROR   Thread-10 :1776 [internal_api.py:execute():126] 429 response executing GraphQL.
2021-03-14 00:42:28,782 ERROR   Thread-10 :1776 [internal_api.py:execute():127] {"error":"rate limit exceeded"}

2021-03-14 00:42:40,623 ERROR   Thread-10 :1776 [internal_api.py:execute():126] 429 response executing GraphQL.
2021-03-14 00:42:40,625 ERROR   Thread-10 :1776 [internal_api.py:execute():127] {"error":"rate limit exceeded"}

2021-03-14 00:42:42,160 ERROR   Thread-10 :1776 [internal_api.py:execute():126] 429 response executing GraphQL.
2021-03-14 00:42:42,162 ERROR   Thread-10 :1776 [internal_api.py:execute():127] {"error":"rate limit exceeded"}

2021-03-14 00:42:44,683 ERROR   Thread-10 :1776 [internal_api.py:execute():126] 429 response executing GraphQL.
2021-03-14 00:42:44,684 ERROR   Thread-10 :1776 [internal_api.py:execute():127] {"error":"rate limit exceeded"}

2021-03-14 00:42:44,684 ERROR   Thread-10 :1776 [retry.py:__call__():111] Retry attempt failed:
Traceback (most recent call last):
  File "C:\Users\rigve\AppData\Roaming\Python\Python38\site-packages\wandb\old\retry.py", line 96, in __call__
    result = self._call_fn(*args, **kwargs)
  File "C:\Users\rigve\AppData\Roaming\Python\Python38\site-packages\wandb\sdk\internal\internal_api.py", line 129, in execute
    six.reraise(*sys.exc_info())
  File "C:\Users\rigve\AppData\Roaming\Python\Python38\site-packages\six.py", line 703, in reraise
    raise value
  File "C:\Users\rigve\AppData\Roaming\Python\Python38\site-packages\wandb\sdk\internal\internal_api.py", line 123, in execute
    return self.client.execute(*args, **kwargs)
  File "C:\Users\rigve\AppData\Roaming\Python\Python38\site-packages\wandb\vendor\gql-0.2.0\gql\client.py", line 52, in execute
    result = self._get_result(document, *args, **kwargs)
  File "C:\Users\rigve\AppData\Roaming\Python\Python38\site-packages\wandb\vendor\gql-0.2.0\gql\client.py", line 60, in _get_result
    return self.transport.execute(document, *args, **kwargs)
  File "C:\Users\rigve\AppData\Roaming\Python\Python38\site-packages\wandb\vendor\gql-0.2.0\gql\transport\requests.py", line 39, in execute
    request.raise_for_status()
  File "C:\Users\rigve\AppData\Roaming\Python\Python38\site-packages\requests\models.py", line 943, in raise_for_status
    raise HTTPError(http_error_msg, response=self)
requests.exceptions.HTTPError: 429 Client Error: Too Many Requests for url: https://api.wandb.ai/graphql
2021-03-14 00:42:58,604 ERROR   Thread-10 :1776 [internal_api.py:execute():126] 429 response executing GraphQL.
2021-03-14 00:42:58,604 ERROR   Thread-10 :1776 [internal_api.py:execute():127] {"error":"rate limit exceeded"}

2021-03-14 00:43:12,267 ERROR   Thread-10 :1776 [internal_api.py:execute():126] 429 response executing GraphQL.
2021-03-14 00:43:12,267 ERROR   Thread-10 :1776 [internal_api.py:execute():127] {"error":"rate limit exceeded"}

2021-03-14 00:43:13,910 ERROR   Thread-10 :1776 [internal_api.py:execute():126] 429 response executing GraphQL.
2021-03-14 00:43:13,910 ERROR   Thread-10 :1776 [internal_api.py:execute():127] {"error":"rate limit exceeded"}

2021-03-14 00:43:26,909 ERROR   Thread-10 :1776 [internal_api.py:execute():126] 429 response executing GraphQL.
2021-03-14 00:43:26,910 ERROR   Thread-10 :1776 [internal_api.py:execute():127] {"error":"rate limit exceeded"}

2021-03-14 00:43:28,657 ERROR   Thread-10 :1776 [internal_api.py:execute():126] 429 response executing GraphQL.
2021-03-14 00:43:28,657 ERROR   Thread-10 :1776 [internal_api.py:execute():127] {"error":"rate limit exceeded"}

2021-03-14 00:43:41,656 ERROR   Thread-10 :1776 [internal_api.py:execute():126] 429 response executing GraphQL.
2021-03-14 00:43:41,656 ERROR   Thread-10 :1776 [internal_api.py:execute():127] {"error":"rate limit exceeded"}

2021-03-14 00:43:43,295 ERROR   Thread-10 :1776 [internal_api.py:execute():126] 429 response executing GraphQL.
2021-03-14 00:43:43,296 ERROR   Thread-10 :1776 [internal_api.py:execute():127] {"error":"rate limit exceeded"}

2021-03-14 00:43:59,895 ERROR   Thread-10 :1776 [internal_api.py:execute():126] 429 response executing GraphQL.
2021-03-14 00:43:59,895 ERROR   Thread-10 :1776 [internal_api.py:execute():127] {"error":"rate limit exceeded"}

2021-03-14 00:44:11,669 ERROR   Thread-10 :1776 [internal_api.py:execute():126] 429 response executing GraphQL.
2021-03-14 00:44:11,669 ERROR   Thread-10 :1776 [internal_api.py:execute():127] {"error":"rate limit exceeded"}

2021-03-14 00:44:13,299 ERROR   Thread-10 :1776 [internal_api.py:execute():126] 429 response executing GraphQL.
2021-03-14 00:44:13,299 ERROR   Thread-10 :1776 [internal_api.py:execute():127] {"error":"rate limit exceeded"}

2021-03-14 00:44:41,849 ERROR   Thread-10 :1776 [internal_api.py:execute():126] 429 response executing GraphQL.
2021-03-14 00:44:41,850 ERROR   Thread-10 :1776 [internal_api.py:execute():127] {"error":"rate limit exceeded"}

2021-03-14 00:44:43,304 ERROR   Thread-10 :1776 [internal_api.py:execute():126] 429 response executing GraphQL.
2021-03-14 00:44:43,306 ERROR   Thread-10 :1776 [internal_api.py:execute():127] {"error":"rate limit exceeded"}

2021-03-14 00:44:57,729 ERROR   Thread-10 :1776 [internal_api.py:execute():126] 429 response executing GraphQL.
2021-03-14 00:44:57,730 ERROR   Thread-10 :1776 [internal_api.py:execute():127] {"error":"rate limit exceeded"}

2021-03-14 00:44:59,382 ERROR   Thread-10 :1776 [internal_api.py:execute():126] 429 response executing GraphQL.
2021-03-14 00:44:59,384 ERROR   Thread-10 :1776 [internal_api.py:execute():127] {"error":"rate limit exceeded"}

2021-03-14 00:45:11,748 ERROR   Thread-10 :1776 [internal_api.py:execute():126] 429 response executing GraphQL.
2021-03-14 00:45:11,750 ERROR   Thread-10 :1776 [internal_api.py:execute():127] {"error":"rate limit exceeded"}

2021-03-14 00:45:13,225 ERROR   Thread-10 :1776 [internal_api.py:execute():126] 429 response executing GraphQL.
2021-03-14 00:45:13,226 ERROR   Thread-10 :1776 [internal_api.py:execute():127] {"error":"rate limit exceeded"}

2021-03-14 00:45:27,221 ERROR   Thread-10 :1776 [internal_api.py:execute():126] 429 response executing GraphQL.
2021-03-14 00:45:27,221 ERROR   Thread-10 :1776 [internal_api.py:execute():127] {"error":"rate limit exceeded"}

2021-03-14 00:45:28,842 ERROR   Thread-10 :1776 [internal_api.py:execute():126] 429 response executing GraphQL.
2021-03-14 00:45:28,843 ERROR   Thread-10 :1776 [internal_api.py:execute():127] {"error":"rate limit exceeded"}

2021-03-14 00:45:42,187 ERROR   Thread-10 :1776 [internal_api.py:execute():126] 429 response executing GraphQL.
2021-03-14 00:45:42,189 ERROR   Thread-10 :1776 [internal_api.py:execute():127] {"error":"rate limit exceeded"}

2021-03-14 00:45:43,721 ERROR   Thread-10 :1776 [internal_api.py:execute():126] 429 response executing GraphQL.
2021-03-14 00:45:43,722 ERROR   Thread-10 :1776 [internal_api.py:execute():127] {"error":"rate limit exceeded"}

2021-03-14 00:45:57,474 ERROR   Thread-10 :1776 [internal_api.py:execute():126] 429 response executing GraphQL.
2021-03-14 00:45:57,475 ERROR   Thread-10 :1776 [internal_api.py:execute():127] {"error":"rate limit exceeded"}

2021-03-14 00:45:59,020 ERROR   Thread-10 :1776 [internal_api.py:execute():126] 429 response executing GraphQL.
2021-03-14 00:45:59,020 ERROR   Thread-10 :1776 [internal_api.py:execute():127] {"error":"rate limit exceeded"}

2021-03-14 00:46:11,070 ERROR   Thread-10 :1776 [internal_api.py:execute():126] 429 response executing GraphQL.
2021-03-14 00:46:11,082 ERROR   Thread-10 :1776 [internal_api.py:execute():127] {"error":"rate limit exceeded"}

2021-03-14 00:46:12,806 ERROR   Thread-10 :1776 [internal_api.py:execute():126] 429 response executing GraphQL.
2021-03-14 00:46:12,807 ERROR   Thread-10 :1776 [internal_api.py:execute():127] {"error":"rate limit exceeded"}

2021-03-14 00:46:29,228 ERROR   Thread-10 :1776 [internal_api.py:execute():126] 429 response executing GraphQL.
2021-03-14 00:46:29,228 ERROR   Thread-10 :1776 [internal_api.py:execute():127] {"error":"rate limit exceeded"}

2021-03-14 00:46:40,890 ERROR   Thread-10 :1776 [internal_api.py:execute():126] 429 response executing GraphQL.
2021-03-14 00:46:40,890 ERROR   Thread-10 :1776 [internal_api.py:execute():127] {"error":"rate limit exceeded"}

2021-03-14 00:46:42,502 ERROR   Thread-10 :1776 [internal_api.py:execute():126] 429 response executing GraphQL.
2021-03-14 00:46:42,502 ERROR   Thread-10 :1776 [internal_api.py:execute():127] {"error":"rate limit exceeded"}

2021-03-14 00:46:59,910 ERROR   Thread-10 :1776 [internal_api.py:execute():126] 429 response executing GraphQL.
2021-03-14 00:46:59,910 ERROR   Thread-10 :1776 [internal_api.py:execute():127] {"error":"rate limit exceeded"}

2021-03-14 00:47:11,475 ERROR   Thread-10 :1776 [internal_api.py:execute():126] 429 response executing GraphQL.
2021-03-14 00:47:11,475 ERROR   Thread-10 :1776 [internal_api.py:execute():127] {"error":"rate limit exceeded"}

2021-03-14 00:47:13,301 ERROR   Thread-10 :1776 [internal_api.py:execute():126] 429 response executing GraphQL.
2021-03-14 00:47:13,312 ERROR   Thread-10 :1776 [internal_api.py:execute():127] {"error":"rate limit exceeded"}

2021-03-14 00:47:29,606 ERROR   Thread-10 :1776 [internal_api.py:execute():126] 429 response executing GraphQL.
2021-03-14 00:47:29,606 ERROR   Thread-10 :1776 [internal_api.py:execute():127] {"error":"rate limit exceeded"}

2021-03-14 00:47:41,074 ERROR   Thread-10 :1776 [internal_api.py:execute():126] 429 response executing GraphQL.
2021-03-14 00:47:41,074 ERROR   Thread-10 :1776 [internal_api.py:execute():127] {"error":"rate limit exceeded"}

2021-03-14 00:47:42,797 ERROR   Thread-10 :1776 [internal_api.py:execute():126] 429 response executing GraphQL.
2021-03-14 00:47:42,799 ERROR   Thread-10 :1776 [internal_api.py:execute():127] {"error":"rate limit exceeded"}

2021-03-14 00:47:58,791 ERROR   Thread-10 :1776 [internal_api.py:execute():126] 429 response executing GraphQL.
2021-03-14 00:47:58,791 ERROR   Thread-10 :1776 [internal_api.py:execute():127] {"error":"rate limit exceeded"}

2021-03-14 00:48:13,045 ERROR   Thread-10 :1776 [internal_api.py:execute():126] 429 response executing GraphQL.
2021-03-14 00:48:13,045 ERROR   Thread-10 :1776 [internal_api.py:execute():127] {"error":"rate limit exceeded"}

2021-03-14 00:48:14,681 ERROR   Thread-10 :1776 [internal_api.py:execute():126] 429 response executing GraphQL.
2021-03-14 00:48:14,681 ERROR   Thread-10 :1776 [internal_api.py:execute():127] {"error":"rate limit exceeded"}

2021-03-14 00:48:26,679 ERROR   Thread-10 :1776 [internal_api.py:execute():126] 429 response executing GraphQL.
2021-03-14 00:48:26,679 ERROR   Thread-10 :1776 [internal_api.py:execute():127] {"error":"rate limit exceeded"}

2021-03-14 00:48:28,385 ERROR   Thread-10 :1776 [internal_api.py:execute():126] 429 response executing GraphQL.
2021-03-14 00:48:28,388 ERROR   Thread-10 :1776 [internal_api.py:execute():127] {"error":"rate limit exceeded"}

2021-03-14 00:48:43,971 ERROR   Thread-10 :1776 [internal_api.py:execute():126] 429 response executing GraphQL.
2021-03-14 00:48:43,971 ERROR   Thread-10 :1776 [internal_api.py:execute():127] {"error":"rate limit exceeded"}

2021-03-14 00:48:57,434 ERROR   Thread-10 :1776 [internal_api.py:execute():126] 429 response executing GraphQL.
2021-03-14 00:48:57,434 ERROR   Thread-10 :1776 [internal_api.py:execute():127] {"error":"rate limit exceeded"}

2021-03-14 00:48:59,041 ERROR   Thread-10 :1776 [internal_api.py:execute():126] 429 response executing GraphQL.
2021-03-14 00:48:59,043 ERROR   Thread-10 :1776 [internal_api.py:execute():127] {"error":"rate limit exceeded"}

2021-03-14 00:49:10,949 ERROR   Thread-10 :1776 [internal_api.py:execute():126] 429 response executing GraphQL.
2021-03-14 00:49:10,963 ERROR   Thread-10 :1776 [internal_api.py:execute():127] {"error":"rate limit exceeded"}

2021-03-14 00:49:12,628 ERROR   Thread-10 :1776 [internal_api.py:execute():126] 429 response executing GraphQL.
2021-03-14 00:49:12,630 ERROR   Thread-10 :1776 [internal_api.py:execute():127] {"error":"rate limit exceeded"}

2021-03-14 00:49:29,314 ERROR   Thread-10 :1776 [internal_api.py:execute():126] 429 response executing GraphQL.
2021-03-14 00:49:29,314 ERROR   Thread-10 :1776 [internal_api.py:execute():127] {"error":"rate limit exceeded"}

2021-03-14 00:49:42,095 ERROR   Thread-10 :1776 [internal_api.py:execute():126] 429 response executing GraphQL.
2021-03-14 00:49:42,095 ERROR   Thread-10 :1776 [internal_api.py:execute():127] {"error":"rate limit exceeded"}

2021-03-14 00:49:44,061 ERROR   Thread-10 :1776 [internal_api.py:execute():126] 429 response executing GraphQL.
2021-03-14 00:49:44,063 ERROR   Thread-10 :1776 [internal_api.py:execute():127] {"error":"rate limit exceeded"}

2021-03-14 00:49:56,862 ERROR   Thread-10 :1776 [internal_api.py:execute():126] 429 response executing GraphQL.
2021-03-14 00:49:56,862 ERROR   Thread-10 :1776 [internal_api.py:execute():127] {"error":"rate limit exceeded"}

2021-03-14 00:49:58,565 ERROR   Thread-10 :1776 [internal_api.py:execute():126] 429 response executing GraphQL.
2021-03-14 00:49:58,566 ERROR   Thread-10 :1776 [internal_api.py:execute():127] {"error":"rate limit exceeded"}

2021-03-14 00:50:12,015 ERROR   Thread-10 :1776 [internal_api.py:execute():126] 429 response executing GraphQL.
2021-03-14 00:50:12,015 ERROR   Thread-10 :1776 [internal_api.py:execute():127] {"error":"rate limit exceeded"}

2021-03-14 00:50:13,574 ERROR   Thread-10 :1776 [internal_api.py:execute():126] 429 response executing GraphQL.
2021-03-14 00:50:13,574 ERROR   Thread-10 :1776 [internal_api.py:execute():127] {"error":"rate limit exceeded"}

2021-03-14 00:50:25,966 ERROR   Thread-10 :1776 [internal_api.py:execute():126] 429 response executing GraphQL.
2021-03-14 00:50:25,966 ERROR   Thread-10 :1776 [internal_api.py:execute():127] {"error":"rate limit exceeded"}

2021-03-14 00:50:27,583 ERROR   Thread-10 :1776 [internal_api.py:execute():126] 429 response executing GraphQL.
2021-03-14 00:50:27,583 ERROR   Thread-10 :1776 [internal_api.py:execute():127] {"error":"rate limit exceeded"}

2021-03-14 00:50:43,769 ERROR   Thread-10 :1776 [internal_api.py:execute():126] 429 response executing GraphQL.
2021-03-14 00:50:43,769 ERROR   Thread-10 :1776 [internal_api.py:execute():127] {"error":"rate limit exceeded"}

2021-03-14 00:50:58,615 ERROR   Thread-10 :1776 [internal_api.py:execute():126] 429 response executing GraphQL.
2021-03-14 00:50:58,616 ERROR   Thread-10 :1776 [internal_api.py:execute():127] {"error":"rate limit exceeded"}

2021-03-14 00:51:00,149 ERROR   Thread-10 :1776 [internal_api.py:execute():126] 429 response executing GraphQL.
2021-03-14 00:51:00,150 ERROR   Thread-10 :1776 [internal_api.py:execute():127] {"error":"rate limit exceeded"}

2021-03-14 00:51:12,334 ERROR   Thread-10 :1776 [internal_api.py:execute():126] 429 response executing GraphQL.
2021-03-14 00:51:12,335 ERROR   Thread-10 :1776 [internal_api.py:execute():127] {"error":"rate limit exceeded"}

2021-03-14 00:51:13,987 ERROR   Thread-10 :1776 [internal_api.py:execute():126] 429 response executing GraphQL.
2021-03-14 00:51:13,987 ERROR   Thread-10 :1776 [internal_api.py:execute():127] {"error":"rate limit exceeded"}

2021-03-14 00:51:25,519 ERROR   Thread-10 :1776 [internal_api.py:execute():126] 429 response executing GraphQL.
2021-03-14 00:51:25,520 ERROR   Thread-10 :1776 [internal_api.py:execute():127] {"error":"rate limit exceeded"}

2021-03-14 00:51:27,159 ERROR   Thread-10 :1776 [internal_api.py:execute():126] 429 response executing GraphQL.
2021-03-14 00:51:27,160 ERROR   Thread-10 :1776 [internal_api.py:execute():127] {"error":"rate limit exceeded"}

2021-03-14 00:51:29,885 ERROR   Thread-10 :1776 [internal_api.py:execute():126] 429 response executing GraphQL.
2021-03-14 00:51:29,885 ERROR   Thread-10 :1776 [internal_api.py:execute():127] {"error":"rate limit exceeded"}

2021-03-14 00:51:29,886 ERROR   Thread-10 :1776 [retry.py:__call__():111] Retry attempt failed:
Traceback (most recent call last):
  File "C:\Users\rigve\AppData\Roaming\Python\Python38\site-packages\wandb\old\retry.py", line 96, in __call__
    result = self._call_fn(*args, **kwargs)
  File "C:\Users\rigve\AppData\Roaming\Python\Python38\site-packages\wandb\sdk\internal\internal_api.py", line 129, in execute
    six.reraise(*sys.exc_info())
  File "C:\Users\rigve\AppData\Roaming\Python\Python38\site-packages\six.py", line 703, in reraise
    raise value
  File "C:\Users\rigve\AppData\Roaming\Python\Python38\site-packages\wandb\sdk\internal\internal_api.py", line 123, in execute
    return self.client.execute(*args, **kwargs)
  File "C:\Users\rigve\AppData\Roaming\Python\Python38\site-packages\wandb\vendor\gql-0.2.0\gql\client.py", line 52, in execute
    result = self._get_result(document, *args, **kwargs)
  File "C:\Users\rigve\AppData\Roaming\Python\Python38\site-packages\wandb\vendor\gql-0.2.0\gql\client.py", line 60, in _get_result
    return self.transport.execute(document, *args, **kwargs)
  File "C:\Users\rigve\AppData\Roaming\Python\Python38\site-packages\wandb\vendor\gql-0.2.0\gql\transport\requests.py", line 39, in execute
    request.raise_for_status()
  File "C:\Users\rigve\AppData\Roaming\Python\Python38\site-packages\requests\models.py", line 943, in raise_for_status
    raise HTTPError(http_error_msg, response=self)
requests.exceptions.HTTPError: 429 Client Error: Too Many Requests for url: https://api.wandb.ai/graphql
2021-03-14 00:51:44,180 ERROR   Thread-10 :1776 [internal_api.py:execute():126] 429 response executing GraphQL.
2021-03-14 00:51:44,182 ERROR   Thread-10 :1776 [internal_api.py:execute():127] {"error":"rate limit exceeded"}

2021-03-14 00:51:57,816 ERROR   Thread-10 :1776 [internal_api.py:execute():126] 429 response executing GraphQL.
2021-03-14 00:51:57,816 ERROR   Thread-10 :1776 [internal_api.py:execute():127] {"error":"rate limit exceeded"}

2021-03-14 00:51:59,383 ERROR   Thread-10 :1776 [internal_api.py:execute():126] 429 response executing GraphQL.
2021-03-14 00:51:59,383 ERROR   Thread-10 :1776 [internal_api.py:execute():127] {"error":"rate limit exceeded"}

2021-03-14 00:52:12,033 ERROR   Thread-10 :1776 [internal_api.py:execute():126] 429 response executing GraphQL.
2021-03-14 00:52:12,035 ERROR   Thread-10 :1776 [internal_api.py:execute():127] {"error":"rate limit exceeded"}

2021-03-14 00:52:13,651 ERROR   Thread-10 :1776 [internal_api.py:execute():126] 429 response executing GraphQL.
2021-03-14 00:52:13,652 ERROR   Thread-10 :1776 [internal_api.py:execute():127] {"error":"rate limit exceeded"}

2021-03-14 00:52:26,781 ERROR   Thread-10 :1776 [internal_api.py:execute():126] 429 response executing GraphQL.
2021-03-14 00:52:26,782 ERROR   Thread-10 :1776 [internal_api.py:execute():127] {"error":"rate limit exceeded"}

2021-03-14 00:52:28,227 ERROR   Thread-10 :1776 [internal_api.py:execute():126] 429 response executing GraphQL.
2021-03-14 00:52:28,228 ERROR   Thread-10 :1776 [internal_api.py:execute():127] {"error":"rate limit exceeded"}

2021-03-14 00:52:42,961 ERROR   Thread-10 :1776 [internal_api.py:execute():126] 429 response executing GraphQL.
2021-03-14 00:52:42,961 ERROR   Thread-10 :1776 [internal_api.py:execute():127] {"error":"rate limit exceeded"}

2021-03-14 00:52:44,634 ERROR   Thread-10 :1776 [internal_api.py:execute():126] 429 response executing GraphQL.
2021-03-14 00:52:44,634 ERROR   Thread-10 :1776 [internal_api.py:execute():127] {"error":"rate limit exceeded"}

2021-03-14 00:52:55,351 ERROR   Thread-10 :1776 [internal_api.py:execute():126] 429 response executing GraphQL.
2021-03-14 00:52:55,353 ERROR   Thread-10 :1776 [internal_api.py:execute():127] {"error":"rate limit exceeded"}

2021-03-14 00:52:57,017 ERROR   Thread-10 :1776 [internal_api.py:execute():126] 429 response executing GraphQL.
2021-03-14 00:52:57,017 ERROR   Thread-10 :1776 [internal_api.py:execute():127] {"error":"rate limit exceeded"}

2021-03-14 00:52:59,548 ERROR   Thread-10 :1776 [internal_api.py:execute():126] 429 response executing GraphQL.
2021-03-14 00:52:59,548 ERROR   Thread-10 :1776 [internal_api.py:execute():127] {"error":"rate limit exceeded"}

2021-03-14 00:52:59,549 ERROR   Thread-10 :1776 [retry.py:__call__():111] Retry attempt failed:
Traceback (most recent call last):
  File "C:\Users\rigve\AppData\Roaming\Python\Python38\site-packages\wandb\old\retry.py", line 96, in __call__
    result = self._call_fn(*args, **kwargs)
  File "C:\Users\rigve\AppData\Roaming\Python\Python38\site-packages\wandb\sdk\internal\internal_api.py", line 129, in execute
    six.reraise(*sys.exc_info())
  File "C:\Users\rigve\AppData\Roaming\Python\Python38\site-packages\six.py", line 703, in reraise
    raise value
  File "C:\Users\rigve\AppData\Roaming\Python\Python38\site-packages\wandb\sdk\internal\internal_api.py", line 123, in execute
    return self.client.execute(*args, **kwargs)
  File "C:\Users\rigve\AppData\Roaming\Python\Python38\site-packages\wandb\vendor\gql-0.2.0\gql\client.py", line 52, in execute
    result = self._get_result(document, *args, **kwargs)
  File "C:\Users\rigve\AppData\Roaming\Python\Python38\site-packages\wandb\vendor\gql-0.2.0\gql\client.py", line 60, in _get_result
    return self.transport.execute(document, *args, **kwargs)
  File "C:\Users\rigve\AppData\Roaming\Python\Python38\site-packages\wandb\vendor\gql-0.2.0\gql\transport\requests.py", line 39, in execute
    request.raise_for_status()
  File "C:\Users\rigve\AppData\Roaming\Python\Python38\site-packages\requests\models.py", line 943, in raise_for_status
    raise HTTPError(http_error_msg, response=self)
requests.exceptions.HTTPError: 429 Client Error: Too Many Requests for url: https://api.wandb.ai/graphql
2021-03-14 00:53:12,638 ERROR   Thread-10 :1776 [internal_api.py:execute():126] 429 response executing GraphQL.
2021-03-14 00:53:12,640 ERROR   Thread-10 :1776 [internal_api.py:execute():127] {"error":"rate limit exceeded"}

2021-03-14 00:53:14,051 ERROR   Thread-10 :1776 [internal_api.py:execute():126] 429 response executing GraphQL.
2021-03-14 00:53:14,053 ERROR   Thread-10 :1776 [internal_api.py:execute():127] {"error":"rate limit exceeded"}

2021-03-14 00:53:24,843 ERROR   Thread-10 :1776 [internal_api.py:execute():126] 429 response executing GraphQL.
2021-03-14 00:53:24,845 ERROR   Thread-10 :1776 [internal_api.py:execute():127] {"error":"rate limit exceeded"}

2021-03-14 00:53:26,379 ERROR   Thread-10 :1776 [internal_api.py:execute():126] 429 response executing GraphQL.
2021-03-14 00:53:26,379 ERROR   Thread-10 :1776 [internal_api.py:execute():127] {"error":"rate limit exceeded"}

2021-03-14 00:53:29,356 ERROR   Thread-10 :1776 [internal_api.py:execute():126] 429 response executing GraphQL.
2021-03-14 00:53:29,356 ERROR   Thread-10 :1776 [internal_api.py:execute():127] {"error":"rate limit exceeded"}

2021-03-14 00:53:29,357 ERROR   Thread-10 :1776 [retry.py:__call__():111] Retry attempt failed:
Traceback (most recent call last):
  File "C:\Users\rigve\AppData\Roaming\Python\Python38\site-packages\wandb\old\retry.py", line 96, in __call__
    result = self._call_fn(*args, **kwargs)
  File "C:\Users\rigve\AppData\Roaming\Python\Python38\site-packages\wandb\sdk\internal\internal_api.py", line 129, in execute
    six.reraise(*sys.exc_info())
  File "C:\Users\rigve\AppData\Roaming\Python\Python38\site-packages\six.py", line 703, in reraise
    raise value
  File "C:\Users\rigve\AppData\Roaming\Python\Python38\site-packages\wandb\sdk\internal\internal_api.py", line 123, in execute
    return self.client.execute(*args, **kwargs)
  File "C:\Users\rigve\AppData\Roaming\Python\Python38\site-packages\wandb\vendor\gql-0.2.0\gql\client.py", line 52, in execute
    result = self._get_result(document, *args, **kwargs)
  File "C:\Users\rigve\AppData\Roaming\Python\Python38\site-packages\wandb\vendor\gql-0.2.0\gql\client.py", line 60, in _get_result
    return self.transport.execute(document, *args, **kwargs)
  File "C:\Users\rigve\AppData\Roaming\Python\Python38\site-packages\wandb\vendor\gql-0.2.0\gql\transport\requests.py", line 39, in execute
    request.raise_for_status()
  File "C:\Users\rigve\AppData\Roaming\Python\Python38\site-packages\requests\models.py", line 943, in raise_for_status
    raise HTTPError(http_error_msg, response=self)
requests.exceptions.HTTPError: 429 Client Error: Too Many Requests for url: https://api.wandb.ai/graphql
2021-03-14 00:53:42,377 ERROR   Thread-10 :1776 [internal_api.py:execute():126] 429 response executing GraphQL.
2021-03-14 00:53:42,377 ERROR   Thread-10 :1776 [internal_api.py:execute():127] {"error":"rate limit exceeded"}

2021-03-14 00:53:44,095 ERROR   Thread-10 :1776 [internal_api.py:execute():126] 429 response executing GraphQL.
2021-03-14 00:53:44,096 ERROR   Thread-10 :1776 [internal_api.py:execute():127] {"error":"rate limit exceeded"}

2021-03-14 00:53:54,917 ERROR   Thread-10 :1776 [internal_api.py:execute():126] 429 response executing GraphQL.
2021-03-14 00:53:54,917 ERROR   Thread-10 :1776 [internal_api.py:execute():127] {"error":"rate limit exceeded"}

2021-03-14 00:53:56,483 ERROR   Thread-10 :1776 [internal_api.py:execute():126] 429 response executing GraphQL.
2021-03-14 00:53:56,484 ERROR   Thread-10 :1776 [internal_api.py:execute():127] {"error":"rate limit exceeded"}

2021-03-14 00:53:59,081 ERROR   Thread-10 :1776 [internal_api.py:execute():126] 429 response executing GraphQL.
2021-03-14 00:53:59,082 ERROR   Thread-10 :1776 [internal_api.py:execute():127] {"error":"rate limit exceeded"}

2021-03-14 00:53:59,083 ERROR   Thread-10 :1776 [retry.py:__call__():111] Retry attempt failed:
Traceback (most recent call last):
  File "C:\Users\rigve\AppData\Roaming\Python\Python38\site-packages\wandb\old\retry.py", line 96, in __call__
    result = self._call_fn(*args, **kwargs)
  File "C:\Users\rigve\AppData\Roaming\Python\Python38\site-packages\wandb\sdk\internal\internal_api.py", line 129, in execute
    six.reraise(*sys.exc_info())
  File "C:\Users\rigve\AppData\Roaming\Python\Python38\site-packages\six.py", line 703, in reraise
    raise value
  File "C:\Users\rigve\AppData\Roaming\Python\Python38\site-packages\wandb\sdk\internal\internal_api.py", line 123, in execute
    return self.client.execute(*args, **kwargs)
  File "C:\Users\rigve\AppData\Roaming\Python\Python38\site-packages\wandb\vendor\gql-0.2.0\gql\client.py", line 52, in execute
    result = self._get_result(document, *args, **kwargs)
  File "C:\Users\rigve\AppData\Roaming\Python\Python38\site-packages\wandb\vendor\gql-0.2.0\gql\client.py", line 60, in _get_result
    return self.transport.execute(document, *args, **kwargs)
  File "C:\Users\rigve\AppData\Roaming\Python\Python38\site-packages\wandb\vendor\gql-0.2.0\gql\transport\requests.py", line 39, in execute
    request.raise_for_status()
  File "C:\Users\rigve\AppData\Roaming\Python\Python38\site-packages\requests\models.py", line 943, in raise_for_status
    raise HTTPError(http_error_msg, response=self)
requests.exceptions.HTTPError: 429 Client Error: Too Many Requests for url: https://api.wandb.ai/graphql
2021-03-14 00:54:11,528 ERROR   Thread-10 :1776 [internal_api.py:execute():126] 429 response executing GraphQL.
2021-03-14 00:54:11,531 ERROR   Thread-10 :1776 [internal_api.py:execute():127] {"error":"rate limit exceeded"}

2021-03-14 00:54:13,177 ERROR   Thread-10 :1776 [internal_api.py:execute():126] 429 response executing GraphQL.
2021-03-14 00:54:13,177 ERROR   Thread-10 :1776 [internal_api.py:execute():127] {"error":"rate limit exceeded"}

2021-03-14 00:54:28,537 ERROR   Thread-10 :1776 [internal_api.py:execute():126] 429 response executing GraphQL.
2021-03-14 00:54:28,537 ERROR   Thread-10 :1776 [internal_api.py:execute():127] {"error":"rate limit exceeded"}

2021-03-14 00:54:30,174 ERROR   Thread-10 :1776 [internal_api.py:execute():126] 429 response executing GraphQL.
2021-03-14 00:54:30,174 ERROR   Thread-10 :1776 [internal_api.py:execute():127] {"error":"rate limit exceeded"}

2021-03-14 00:54:40,725 ERROR   Thread-10 :1776 [internal_api.py:execute():126] 429 response executing GraphQL.
2021-03-14 00:54:40,728 ERROR   Thread-10 :1776 [internal_api.py:execute():127] {"error":"rate limit exceeded"}

2021-03-14 00:54:42,357 ERROR   Thread-10 :1776 [internal_api.py:execute():126] 429 response executing GraphQL.
2021-03-14 00:54:42,358 ERROR   Thread-10 :1776 [internal_api.py:execute():127] {"error":"rate limit exceeded"}

2021-03-14 00:54:57,423 ERROR   Thread-10 :1776 [internal_api.py:execute():126] 429 response executing GraphQL.
2021-03-14 00:54:57,424 ERROR   Thread-10 :1776 [internal_api.py:execute():127] {"error":"rate limit exceeded"}

2021-03-14 00:54:58,923 ERROR   Thread-10 :1776 [internal_api.py:execute():126] 429 response executing GraphQL.
2021-03-14 00:54:58,925 ERROR   Thread-10 :1776 [internal_api.py:execute():127] {"error":"rate limit exceeded"}

2021-03-14 00:55:10,011 ERROR   Thread-10 :1776 [internal_api.py:execute():126] 429 response executing GraphQL.
2021-03-14 00:55:10,013 ERROR   Thread-10 :1776 [internal_api.py:execute():127] {"error":"rate limit exceeded"}

2021-03-14 00:55:11,548 ERROR   Thread-10 :1776 [internal_api.py:execute():126] 429 response executing GraphQL.
2021-03-14 00:55:11,550 ERROR   Thread-10 :1776 [internal_api.py:execute():127] {"error":"rate limit exceeded"}

2021-03-14 00:55:14,417 ERROR   Thread-10 :1776 [internal_api.py:execute():126] 429 response executing GraphQL.
2021-03-14 00:55:14,417 ERROR   Thread-10 :1776 [internal_api.py:execute():127] {"error":"rate limit exceeded"}

2021-03-14 00:55:14,420 ERROR   Thread-10 :1776 [retry.py:__call__():111] Retry attempt failed:
Traceback (most recent call last):
  File "C:\Users\rigve\AppData\Roaming\Python\Python38\site-packages\wandb\old\retry.py", line 96, in __call__
    result = self._call_fn(*args, **kwargs)
  File "C:\Users\rigve\AppData\Roaming\Python\Python38\site-packages\wandb\sdk\internal\internal_api.py", line 129, in execute
    six.reraise(*sys.exc_info())
  File "C:\Users\rigve\AppData\Roaming\Python\Python38\site-packages\six.py", line 703, in reraise
    raise value
  File "C:\Users\rigve\AppData\Roaming\Python\Python38\site-packages\wandb\sdk\internal\internal_api.py", line 123, in execute
    return self.client.execute(*args, **kwargs)
  File "C:\Users\rigve\AppData\Roaming\Python\Python38\site-packages\wandb\vendor\gql-0.2.0\gql\client.py", line 52, in execute
    result = self._get_result(document, *args, **kwargs)
  File "C:\Users\rigve\AppData\Roaming\Python\Python38\site-packages\wandb\vendor\gql-0.2.0\gql\client.py", line 60, in _get_result
    return self.transport.execute(document, *args, **kwargs)
  File "C:\Users\rigve\AppData\Roaming\Python\Python38\site-packages\wandb\vendor\gql-0.2.0\gql\transport\requests.py", line 39, in execute
    request.raise_for_status()
  File "C:\Users\rigve\AppData\Roaming\Python\Python38\site-packages\requests\models.py", line 943, in raise_for_status
    raise HTTPError(http_error_msg, response=self)
requests.exceptions.HTTPError: 429 Client Error: Too Many Requests for url: https://api.wandb.ai/graphql
2021-03-14 00:55:26,396 ERROR   Thread-10 :1776 [internal_api.py:execute():126] 429 response executing GraphQL.
2021-03-14 00:55:26,396 ERROR   Thread-10 :1776 [internal_api.py:execute():127] {"error":"rate limit exceeded"}

2021-03-14 00:55:27,985 ERROR   Thread-10 :1776 [internal_api.py:execute():126] 429 response executing GraphQL.
2021-03-14 00:55:27,986 ERROR   Thread-10 :1776 [internal_api.py:execute():127] {"error":"rate limit exceeded"}

2021-03-14 00:55:43,293 ERROR   Thread-10 :1776 [internal_api.py:execute():126] 429 response executing GraphQL.
2021-03-14 00:55:43,293 ERROR   Thread-10 :1776 [internal_api.py:execute():127] {"error":"rate limit exceeded"}

2021-03-14 00:55:44,836 ERROR   Thread-10 :1776 [internal_api.py:execute():126] 429 response executing GraphQL.
2021-03-14 00:55:44,837 ERROR   Thread-10 :1776 [internal_api.py:execute():127] {"error":"rate limit exceeded"}

2021-03-14 00:55:55,478 ERROR   Thread-10 :1776 [internal_api.py:execute():126] 429 response executing GraphQL.
2021-03-14 00:55:55,480 ERROR   Thread-10 :1776 [internal_api.py:execute():127] {"error":"rate limit exceeded"}

2021-03-14 00:55:57,014 ERROR   Thread-10 :1776 [internal_api.py:execute():126] 429 response executing GraphQL.
2021-03-14 00:55:57,017 ERROR   Thread-10 :1776 [internal_api.py:execute():127] {"error":"rate limit exceeded"}

2021-03-14 00:55:59,574 ERROR   Thread-10 :1776 [internal_api.py:execute():126] 429 response executing GraphQL.
2021-03-14 00:55:59,576 ERROR   Thread-10 :1776 [internal_api.py:execute():127] {"error":"rate limit exceeded"}

2021-03-14 00:55:59,576 ERROR   Thread-10 :1776 [retry.py:__call__():111] Retry attempt failed:
Traceback (most recent call last):
  File "C:\Users\rigve\AppData\Roaming\Python\Python38\site-packages\wandb\old\retry.py", line 96, in __call__
    result = self._call_fn(*args, **kwargs)
  File "C:\Users\rigve\AppData\Roaming\Python\Python38\site-packages\wandb\sdk\internal\internal_api.py", line 129, in execute
    six.reraise(*sys.exc_info())
  File "C:\Users\rigve\AppData\Roaming\Python\Python38\site-packages\six.py", line 703, in reraise
    raise value
  File "C:\Users\rigve\AppData\Roaming\Python\Python38\site-packages\wandb\sdk\internal\internal_api.py", line 123, in execute
    return self.client.execute(*args, **kwargs)
  File "C:\Users\rigve\AppData\Roaming\Python\Python38\site-packages\wandb\vendor\gql-0.2.0\gql\client.py", line 52, in execute
    result = self._get_result(document, *args, **kwargs)
  File "C:\Users\rigve\AppData\Roaming\Python\Python38\site-packages\wandb\vendor\gql-0.2.0\gql\client.py", line 60, in _get_result
    return self.transport.execute(document, *args, **kwargs)
  File "C:\Users\rigve\AppData\Roaming\Python\Python38\site-packages\wandb\vendor\gql-0.2.0\gql\transport\requests.py", line 39, in execute
    request.raise_for_status()
  File "C:\Users\rigve\AppData\Roaming\Python\Python38\site-packages\requests\models.py", line 943, in raise_for_status
    raise HTTPError(http_error_msg, response=self)
requests.exceptions.HTTPError: 429 Client Error: Too Many Requests for url: https://api.wandb.ai/graphql
2021-03-14 00:56:12,682 ERROR   Thread-10 :1776 [internal_api.py:execute():126] 429 response executing GraphQL.
2021-03-14 00:56:12,683 ERROR   Thread-10 :1776 [internal_api.py:execute():127] {"error":"rate limit exceeded"}

2021-03-14 00:56:14,320 ERROR   Thread-10 :1776 [internal_api.py:execute():126] 429 response executing GraphQL.
2021-03-14 00:56:14,322 ERROR   Thread-10 :1776 [internal_api.py:execute():127] {"error":"rate limit exceeded"}

2021-03-14 00:56:24,512 ERROR   Thread-10 :1776 [internal_api.py:execute():126] 429 response executing GraphQL.
2021-03-14 00:56:24,512 ERROR   Thread-10 :1776 [internal_api.py:execute():127] {"error":"rate limit exceeded"}

2021-03-14 00:56:25,996 ERROR   Thread-10 :1776 [internal_api.py:execute():126] 429 response executing GraphQL.
2021-03-14 00:56:25,997 ERROR   Thread-10 :1776 [internal_api.py:execute():127] {"error":"rate limit exceeded"}

2021-03-14 00:56:28,455 ERROR   Thread-10 :1776 [internal_api.py:execute():126] 429 response executing GraphQL.
2021-03-14 00:56:28,456 ERROR   Thread-10 :1776 [internal_api.py:execute():127] {"error":"rate limit exceeded"}

2021-03-14 00:56:28,456 ERROR   Thread-10 :1776 [retry.py:__call__():111] Retry attempt failed:
Traceback (most recent call last):
  File "C:\Users\rigve\AppData\Roaming\Python\Python38\site-packages\wandb\old\retry.py", line 96, in __call__
    result = self._call_fn(*args, **kwargs)
  File "C:\Users\rigve\AppData\Roaming\Python\Python38\site-packages\wandb\sdk\internal\internal_api.py", line 129, in execute
    six.reraise(*sys.exc_info())
  File "C:\Users\rigve\AppData\Roaming\Python\Python38\site-packages\six.py", line 703, in reraise
    raise value
  File "C:\Users\rigve\AppData\Roaming\Python\Python38\site-packages\wandb\sdk\internal\internal_api.py", line 123, in execute
    return self.client.execute(*args, **kwargs)
  File "C:\Users\rigve\AppData\Roaming\Python\Python38\site-packages\wandb\vendor\gql-0.2.0\gql\client.py", line 52, in execute
    result = self._get_result(document, *args, **kwargs)
  File "C:\Users\rigve\AppData\Roaming\Python\Python38\site-packages\wandb\vendor\gql-0.2.0\gql\client.py", line 60, in _get_result
    return self.transport.execute(document, *args, **kwargs)
  File "C:\Users\rigve\AppData\Roaming\Python\Python38\site-packages\wandb\vendor\gql-0.2.0\gql\transport\requests.py", line 39, in execute
    request.raise_for_status()
  File "C:\Users\rigve\AppData\Roaming\Python\Python38\site-packages\requests\models.py", line 943, in raise_for_status
    raise HTTPError(http_error_msg, response=self)
requests.exceptions.HTTPError: 429 Client Error: Too Many Requests for url: https://api.wandb.ai/graphql
2021-03-14 00:56:41,970 ERROR   Thread-10 :1776 [internal_api.py:execute():126] 429 response executing GraphQL.
2021-03-14 00:56:41,971 ERROR   Thread-10 :1776 [internal_api.py:execute():127] {"error":"rate limit exceeded"}

2021-03-14 00:56:43,583 ERROR   Thread-10 :1776 [internal_api.py:execute():126] 429 response executing GraphQL.
2021-03-14 00:56:43,585 ERROR   Thread-10 :1776 [internal_api.py:execute():127] {"error":"rate limit exceeded"}

2021-03-14 00:56:57,825 ERROR   Thread-10 :1776 [internal_api.py:execute():126] 429 response executing GraphQL.
2021-03-14 00:56:57,825 ERROR   Thread-10 :1776 [internal_api.py:execute():127] {"error":"rate limit exceeded"}

2021-03-14 00:56:59,241 ERROR   Thread-10 :1776 [internal_api.py:execute():126] 429 response executing GraphQL.
2021-03-14 00:56:59,242 ERROR   Thread-10 :1776 [internal_api.py:execute():127] {"error":"rate limit exceeded"}

2021-03-14 00:57:10,438 ERROR   Thread-10 :1776 [internal_api.py:execute():126] 429 response executing GraphQL.
2021-03-14 00:57:10,439 ERROR   Thread-10 :1776 [internal_api.py:execute():127] {"error":"rate limit exceeded"}

2021-03-14 00:57:11,975 ERROR   Thread-10 :1776 [internal_api.py:execute():126] 429 response executing GraphQL.
2021-03-14 00:57:11,975 ERROR   Thread-10 :1776 [internal_api.py:execute():127] {"error":"rate limit exceeded"}

2021-03-14 00:57:14,487 ERROR   Thread-10 :1776 [internal_api.py:execute():126] 429 response executing GraphQL.
2021-03-14 00:57:14,489 ERROR   Thread-10 :1776 [internal_api.py:execute():127] {"error":"rate limit exceeded"}

2021-03-14 00:57:14,490 ERROR   Thread-10 :1776 [retry.py:__call__():111] Retry attempt failed:
Traceback (most recent call last):
  File "C:\Users\rigve\AppData\Roaming\Python\Python38\site-packages\wandb\old\retry.py", line 96, in __call__
    result = self._call_fn(*args, **kwargs)
  File "C:\Users\rigve\AppData\Roaming\Python\Python38\site-packages\wandb\sdk\internal\internal_api.py", line 129, in execute
    six.reraise(*sys.exc_info())
  File "C:\Users\rigve\AppData\Roaming\Python\Python38\site-packages\six.py", line 703, in reraise
    raise value
  File "C:\Users\rigve\AppData\Roaming\Python\Python38\site-packages\wandb\sdk\internal\internal_api.py", line 123, in execute
    return self.client.execute(*args, **kwargs)
  File "C:\Users\rigve\AppData\Roaming\Python\Python38\site-packages\wandb\vendor\gql-0.2.0\gql\client.py", line 52, in execute
    result = self._get_result(document, *args, **kwargs)
  File "C:\Users\rigve\AppData\Roaming\Python\Python38\site-packages\wandb\vendor\gql-0.2.0\gql\client.py", line 60, in _get_result
    return self.transport.execute(document, *args, **kwargs)
  File "C:\Users\rigve\AppData\Roaming\Python\Python38\site-packages\wandb\vendor\gql-0.2.0\gql\transport\requests.py", line 39, in execute
    request.raise_for_status()
  File "C:\Users\rigve\AppData\Roaming\Python\Python38\site-packages\requests\models.py", line 943, in raise_for_status
    raise HTTPError(http_error_msg, response=self)
requests.exceptions.HTTPError: 429 Client Error: Too Many Requests for url: https://api.wandb.ai/graphql
2021-03-14 00:57:27,283 ERROR   Thread-10 :1776 [internal_api.py:execute():126] 429 response executing GraphQL.
2021-03-14 00:57:27,284 ERROR   Thread-10 :1776 [internal_api.py:execute():127] {"error":"rate limit exceeded"}

2021-03-14 00:57:28,989 ERROR   Thread-10 :1776 [internal_api.py:execute():126] 429 response executing GraphQL.
2021-03-14 00:57:28,989 ERROR   Thread-10 :1776 [internal_api.py:execute():127] {"error":"rate limit exceeded"}

2021-03-14 00:57:41,977 ERROR   Thread-10 :1776 [internal_api.py:execute():126] 429 response executing GraphQL.
2021-03-14 00:57:41,977 ERROR   Thread-10 :1776 [internal_api.py:execute():127] {"error":"rate limit exceeded"}

2021-03-14 00:57:43,493 ERROR   Thread-10 :1776 [internal_api.py:execute():126] 429 response executing GraphQL.
2021-03-14 00:57:43,493 ERROR   Thread-10 :1776 [internal_api.py:execute():127] {"error":"rate limit exceeded"}

2021-03-14 00:57:55,195 ERROR   Thread-10 :1776 [internal_api.py:execute():126] 429 response executing GraphQL.
2021-03-14 00:57:55,196 ERROR   Thread-10 :1776 [internal_api.py:execute():127] {"error":"rate limit exceeded"}

2021-03-14 00:57:56,707 ERROR   Thread-10 :1776 [internal_api.py:execute():126] 429 response executing GraphQL.
2021-03-14 00:57:56,709 ERROR   Thread-10 :1776 [internal_api.py:execute():127] {"error":"rate limit exceeded"}

2021-03-14 00:57:59,662 ERROR   Thread-10 :1776 [internal_api.py:execute():126] 429 response executing GraphQL.
2021-03-14 00:57:59,663 ERROR   Thread-10 :1776 [internal_api.py:execute():127] {"error":"rate limit exceeded"}

2021-03-14 00:57:59,664 ERROR   Thread-10 :1776 [retry.py:__call__():111] Retry attempt failed:
Traceback (most recent call last):
  File "C:\Users\rigve\AppData\Roaming\Python\Python38\site-packages\wandb\old\retry.py", line 96, in __call__
    result = self._call_fn(*args, **kwargs)
  File "C:\Users\rigve\AppData\Roaming\Python\Python38\site-packages\wandb\sdk\internal\internal_api.py", line 129, in execute
    six.reraise(*sys.exc_info())
  File "C:\Users\rigve\AppData\Roaming\Python\Python38\site-packages\six.py", line 703, in reraise
    raise value
  File "C:\Users\rigve\AppData\Roaming\Python\Python38\site-packages\wandb\sdk\internal\internal_api.py", line 123, in execute
    return self.client.execute(*args, **kwargs)
  File "C:\Users\rigve\AppData\Roaming\Python\Python38\site-packages\wandb\vendor\gql-0.2.0\gql\client.py", line 52, in execute
    result = self._get_result(document, *args, **kwargs)
  File "C:\Users\rigve\AppData\Roaming\Python\Python38\site-packages\wandb\vendor\gql-0.2.0\gql\client.py", line 60, in _get_result
    return self.transport.execute(document, *args, **kwargs)
  File "C:\Users\rigve\AppData\Roaming\Python\Python38\site-packages\wandb\vendor\gql-0.2.0\gql\transport\requests.py", line 39, in execute
    request.raise_for_status()
  File "C:\Users\rigve\AppData\Roaming\Python\Python38\site-packages\requests\models.py", line 943, in raise_for_status
    raise HTTPError(http_error_msg, response=self)
requests.exceptions.HTTPError: 429 Client Error: unknown for url: https://api.wandb.ai/graphql
2021-03-14 00:58:11,578 ERROR   Thread-10 :1776 [internal_api.py:execute():126] 429 response executing GraphQL.
2021-03-14 00:58:11,580 ERROR   Thread-10 :1776 [internal_api.py:execute():127] {"error":"rate limit exceeded"}

2021-03-14 00:58:13,222 ERROR   Thread-10 :1776 [internal_api.py:execute():126] 429 response executing GraphQL.
2021-03-14 00:58:13,223 ERROR   Thread-10 :1776 [internal_api.py:execute():127] {"error":"rate limit exceeded"}

2021-03-14 00:58:15,809 INFO    Thread-19 :1776 [wandb_run.py:finish():1139] finishing run rigvedsah/Assignment 1/qanvihog
